<?xml version="1.0" ?>
<!-- =================================================================================== -->
<!-- |    This document was autogenerated by xacro from multi_ur.xacro                 | -->
<!-- |    EDITING THIS FILE BY HAND IS NOT RECOMMENDED                                 | -->
<!-- =================================================================================== -->
<robot name="multi_ur">
  <link name="world"/>
  <joint name="world_to_robot1" type="fixed">
    <parent link="world"/>
    <child link="robot1_base_link"/>
    <origin rpy="0 0 0" xyz="0 0 0"/>
  </joint>
  <!-- LINKS -->
  <link name="robot1_base_link"/>
  <link name="robot1_base_link_inertia">
    <visual>
      <origin rpy="0 0 3.141592653589793" xyz="0 0 0"/>
      <geometry>
        <mesh filename="file:///home/unvrx/URCell/types/ur_description/meshes/ur5/visual/base.dae"/>
      </geometry>
      <material name="LightGrey">
        <color rgba="0.7 0.7 0.7 1.0"/>
      </material>
    </visual>
    <collision>
      <origin rpy="0 0 3.141592653589793" xyz="0 0 0"/>
      <geometry>
        <mesh filename="file:///home/unvrx/URCell/types/ur_description/meshes/ur5/collision/base.stl"/>
      </geometry>
    </collision>
    <inertial>
      <mass value="4.0"/>
      <inertia ixx="0.00443333156" ixy="0.0" ixz="0.0" iyy="0.00443333156" iyz="0.0" izz="0.0072"/>
      <origin rpy="0 0 0" xyz="0 0 0"/>
    </inertial>
  </link>
  <link name="robot1_shoulder_link">
    <inertial>
      <mass value="3.7"/>
      <inertia ixx="0.014972358333333331" ixy="0.0" ixz="0.0" iyy="0.014972358333333331" iyz="0.0" izz="0.01040625"/>
      <origin rpy="0 0 0" xyz="0.0 -0.00193 -0.02561"/>
    </inertial>
    <visual>
      <origin rpy="0 0 3.141592653589793" xyz="0 0 0"/>
      <geometry>
        <mesh filename="file:///home/unvrx/URCell/types/ur_description/meshes/ur5/visual/shoulder.dae"/>
      </geometry>
      <material name="LightGrey">
        <color rgba="0.7 0.7 0.7 1.0"/>
      </material>
    </visual>
    <collision>
      <origin rpy="0 0 3.141592653589793" xyz="0 0 0"/>
      <geometry>
        <mesh filename="file:///home/unvrx/URCell/types/ur_description/meshes/ur5/collision/shoulder.stl"/>
      </geometry>
    </collision>
  </link>
  <link name="robot1_upper_arm_link">
    <inertial>
      <mass value="8.393"/>
      <inertia ixx="0.13388583541666665" ixy="0.0" ixz="0.0" iyy="0.13388583541666665" iyz="0.0" izz="0.0151074"/>
      <origin rpy="0 0 0" xyz="-0.2125 0.0 0.11336"/>
    </inertial>
    <visual>
      <origin rpy="1.5707963267948966 0 -1.5707963267948966" xyz="0 0 0.13585"/>
      <geometry>
        <mesh filename="file:///home/unvrx/URCell/types/ur_description/meshes/ur5/visual/upperarm.dae"/>
      </geometry>
      <material name="LightGrey">
        <color rgba="0.7 0.7 0.7 1.0"/>
      </material>
    </visual>
    <collision>
      <origin rpy="1.5707963267948966 0 -1.5707963267948966" xyz="0 0 0.13585"/>
      <geometry>
        <mesh filename="file:///home/unvrx/URCell/types/ur_description/meshes/ur5/collision/upperarm.stl"/>
      </geometry>
    </collision>
  </link>
  <link name="robot1_forearm_link">
    <inertial>
      <mass value="2.33"/>
      <inertia ixx="0.031216803515624995" ixy="0.0" ixz="0.0" iyy="0.031216803515624995" iyz="0.0" izz="0.004095"/>
      <origin rpy="0 0 0" xyz="-0.24225 0.0 0.0265"/>
    </inertial>
    <visual>
      <origin rpy="1.5707963267948966 0 -1.5707963267948966" xyz="0 0 0.0165"/>
      <geometry>
        <mesh filename="file:///home/unvrx/URCell/types/ur_description/meshes/ur5/visual/forearm.dae"/>
      </geometry>
      <material name="LightGrey">
        <color rgba="0.7 0.7 0.7 1.0"/>
      </material>
    </visual>
    <collision>
      <origin rpy="1.5707963267948966 0 -1.5707963267948966" xyz="0 0 0.0165"/>
      <geometry>
        <mesh filename="file:///home/unvrx/URCell/types/ur_description/meshes/ur5/collision/forearm.stl"/>
      </geometry>
    </collision>
  </link>
  <link name="robot1_wrist_1_link">
    <inertial>
      <mass value="1.219"/>
      <inertia ixx="0.002013889583333333" ixy="0.0" ixz="0.0" iyy="0.002013889583333333" iyz="0.0" izz="0.0021942"/>
      <origin rpy="0 0 0" xyz="0.0 -0.01634 -0.0018"/>
    </inertial>
    <visual>
      <origin rpy="1.5707963267948966 0 0" xyz="0 0 -0.093"/>
      <geometry>
        <mesh filename="file:///home/unvrx/URCell/types/ur_description/meshes/ur5/visual/wrist1.dae"/>
      </geometry>
      <material name="LightGrey">
        <color rgba="0.7 0.7 0.7 1.0"/>
      </material>
    </visual>
    <collision>
      <origin rpy="1.5707963267948966 0 0" xyz="0 0 -0.093"/>
      <geometry>
        <mesh filename="file:///home/unvrx/URCell/types/ur_description/meshes/ur5/collision/wrist1.stl"/>
      </geometry>
    </collision>
  </link>
  <link name="robot1_wrist_2_link">
    <inertial>
      <mass value="1.219"/>
      <inertia ixx="0.0018310395833333333" ixy="0.0" ixz="0.0" iyy="0.0018310395833333333" iyz="0.0" izz="0.0021942"/>
      <origin rpy="0 0 0" xyz="0.0 0.01634 -0.0018"/>
    </inertial>
    <visual>
      <origin rpy="0 0 0" xyz="0 0 -0.095"/>
      <geometry>
        <mesh filename="file:///home/unvrx/URCell/types/ur_description/meshes/ur5/visual/wrist2.dae"/>
      </geometry>
      <material name="LightGrey">
        <color rgba="0.7 0.7 0.7 1.0"/>
      </material>
    </visual>
    <collision>
      <origin rpy="0 0 0" xyz="0 0 -0.095"/>
      <geometry>
        <mesh filename="file:///home/unvrx/URCell/types/ur_description/meshes/ur5/collision/wrist2.stl"/>
      </geometry>
    </collision>
  </link>
  <link name="robot1_wrist_3_link">
    <inertial>
      <mass value="0.1879"/>
      <inertia ixx="8.062475833333332e-05" ixy="0.0" ixz="0.0" iyy="8.062475833333332e-05" iyz="0.0" izz="0.0001321171875"/>
      <origin rpy="0 0 0" xyz="0.0 0.0 -0.001159"/>
    </inertial>
    <visual>
      <origin rpy="1.5707963267948966 0 0" xyz="0 0 -0.0818"/>
      <geometry>
        <mesh filename="file:///home/unvrx/URCell/types/ur_description/meshes/ur5/visual/wrist3.dae"/>
      </geometry>
      <material name="LightGrey">
        <color rgba="0.7 0.7 0.7 1.0"/>
      </material>
    </visual>
    <collision>
      <origin rpy="1.5707963267948966 0 0" xyz="0 0 -0.0818"/>
      <geometry>
        <mesh filename="file:///home/unvrx/URCell/types/ur_description/meshes/ur5/collision/wrist3.stl"/>
      </geometry>
    </collision>
  </link>
  <!-- JOINTS -->
  <joint name="robot1_base_link-base_link_inertia" type="fixed">
    <parent link="robot1_base_link"/>
    <child link="robot1_base_link_inertia"/>
    <origin rpy="0 0 3.141592653589793" xyz="0 0 0"/>
  </joint>
  <joint name="robot1_shoulder_pan_joint" type="revolute">
    <parent link="robot1_base_link_inertia"/>
    <child link="robot1_shoulder_link"/>
    <origin rpy="0 0 0" xyz="0 0 0.089159"/>
    <axis xyz="0 0 1"/>
    <limit effort="150.0" lower="-6.283185307179586" upper="6.283185307179586" velocity="3.141592653589793"/>
  </joint>
  <joint name="robot1_shoulder_lift_joint" type="revolute">
    <parent link="robot1_shoulder_link"/>
    <child link="robot1_upper_arm_link"/>
    <origin rpy="1.570796327 0 0" xyz="0 0 0"/>
    <axis xyz="0 0 1"/>
    <limit effort="150.0" lower="-6.283185307179586" upper="6.283185307179586" velocity="3.141592653589793"/>
  </joint>
  <joint name="robot1_elbow_joint" type="revolute">
    <parent link="robot1_upper_arm_link"/>
    <child link="robot1_forearm_link"/>
    <origin rpy="0 0 0" xyz="-0.425 0 0"/>
    <axis xyz="0 0 1"/>
    <limit effort="150.0" lower="-3.141592653589793" upper="3.141592653589793" velocity="3.141592653589793"/>
  </joint>
  <joint name="robot1_wrist_1_joint" type="revolute">
    <parent link="robot1_forearm_link"/>
    <child link="robot1_wrist_1_link"/>
    <origin rpy="0 0 0" xyz="-0.39225 0 0.10915"/>
    <axis xyz="0 0 1"/>
    <limit effort="150.0" lower="-6.283185307179586" upper="6.283185307179586" velocity="3.141592653589793"/>
  </joint>
  <joint name="robot1_wrist_2_joint" type="revolute">
    <parent link="robot1_wrist_1_link"/>
    <child link="robot1_wrist_2_link"/>
    <origin rpy="1.570796327 0 0" xyz="0 -0.09465 -1.941303950897609e-11"/>
    <axis xyz="0 0 1"/>
    <limit effort="150.0" lower="-6.283185307179586" upper="6.283185307179586" velocity="3.141592653589793"/>
  </joint>
  <joint name="robot1_wrist_3_joint" type="revolute">
    <parent link="robot1_wrist_2_link"/>
    <child link="robot1_wrist_3_link"/>
    <origin rpy="1.570796326589793 3.141592653589793 3.141592653589793" xyz="0 0.0823 -1.688001216681175e-11"/>
    <axis xyz="0 0 1"/>
    <limit effort="150.0" lower="-6.283185307179586" upper="6.283185307179586" velocity="3.141592653589793"/>
  </joint>
  <joint name="world_to_robot2" type="fixed">
    <parent link="world"/>
    <child link="robot2_base_link"/>
    <origin rpy="0 0 0" xyz="0 1 0"/>
  </joint>
  <!-- base_link -->
  <link name="robot2_base_link">
    <visual>
      <geometry>
        <mesh filename="file:///home/unvrx/URCell/types/igus_rebel_description_ros2/meshes/igus_rebel/Joint0.dae"/>
      </geometry>
    </visual>
    <collision>
      <geometry>
        <mesh filename="file:///home/unvrx/URCell/types/igus_rebel_description_ros2/meshes/igus_rebel_mod/Joint0.stl"/>
      </geometry>
    </collision>
    <inertial>
      <mass value="1.0"/>
      <inertia ixx="1.0" ixy="0.0" ixz="0.0" iyy="1.0" iyz="0.0" izz="1.0"/>
    </inertial>
  </link>
  <!-- joint1 -->
  <joint name="robot2_joint1" type="revolute">
    <parent link="robot2_base_link"/>
    <child link="robot2_link_1"/>
    <origin rpy="0.0 0.0 0.0" xyz="0.0 0 0.100"/>
    <axis xyz="0 0 -1"/>
    <limit effort="330.0" lower="-3.12413936106985" upper="3.12413936106985" velocity="0.7853981633974483"/>
  </joint>
  <link name="robot2_link_1">
    <visual>
      <geometry>
        <mesh filename="file:///home/unvrx/URCell/types/igus_rebel_description_ros2/meshes/igus_rebel/Joint1.dae"/>
      </geometry>
      <origin rpy="0 0 0" xyz="0 0 0"/>
    </visual>
    <collision>
      <geometry>
        <mesh filename="file:///home/unvrx/URCell/types/igus_rebel_description_ros2/meshes/igus_rebel_mod/Joint1.stl"/>
      </geometry>
      <origin rpy="0 0 0" xyz="0 0 0"/>
    </collision>
    <inertial>
      <mass value="0.1"/>
      <inertia ixx="0.03" ixy="0.0" ixz="0.0" iyy="0.03" iyz="0.0" izz="0.03"/>
    </inertial>
  </link>
  <!-- joint2 -->
  <joint name="robot2_joint2" type="revolute">
    <parent link="robot2_link_1"/>
    <child link="robot2_link_2"/>
    <origin rpy="0.0 0.5235987755982988 0.0" xyz="0.0 0 0.149"/>
    <axis xyz="0 1 0"/>
    <!-- pi*2/3 are the physical limits, but to avoid any collisions we set the actual limits lower -->
    <limit effort="330.0" lower="-1.9198621771937623" upper="1.9198621771937623" velocity="0.7853981633974483"/>
  </joint>
  <link name="robot2_link_2">
    <visual>
      <geometry>
        <mesh filename="file:///home/unvrx/URCell/types/igus_rebel_description_ros2/meshes/igus_rebel/Joint2.dae"/>
      </geometry>
      <origin rpy="0 0 0" xyz="0 0 0"/>
    </visual>
    <collision>
      <geometry>
        <mesh filename="file:///home/unvrx/URCell/types/igus_rebel_description_ros2/meshes/igus_rebel_mod/Joint2.stl"/>
      </geometry>
      <origin rpy="0 0 0" xyz="0 0 0"/>
    </collision>
    <inertial>
      <mass value="0.1"/>
      <inertia ixx="0.03" ixy="0.0" ixz="0.0" iyy="0.03" iyz="0.0" izz="0.03"/>
    </inertial>
  </link>
  <!-- joint3 -->
  <joint name="robot2_joint3" type="revolute">
    <parent link="robot2_link_2"/>
    <child link="robot2_link_5"/>
    <origin rpy="0.0 0.5235987755982988 0.0" xyz="0.0 0.0 0.2384"/>
    <axis xyz="0 1 0"/>
    <limit effort="330.0" lower="-1.9198621771937623" upper="1.9198621771937623" velocity="0.7853981633974483"/>
  </joint>
  <link name="robot2_link_5">
    <visual>
      <geometry>
        <mesh filename="file:///home/unvrx/URCell/types/igus_rebel_description_ros2/meshes/igus_rebel/Joint3.dae"/>
      </geometry>
      <origin rpy="0 0 0" xyz="0 0 0"/>
    </visual>
    <collision>
      <geometry>
        <mesh filename="file:///home/unvrx/URCell/types/igus_rebel_description_ros2/meshes/igus_rebel_mod/Joint3.stl"/>
      </geometry>
      <origin rpy="0 0 0" xyz="0 0 0"/>
    </collision>
    <inertial>
      <mass value="0.1"/>
      <inertia ixx="0.03" ixy="0.0" ixz="0.0" iyy="0.03" iyz="0.0" izz="0.03"/>
    </inertial>
  </link>
  <!-- joint4 -->
  <joint name="robot2_joint4" type="revolute">
    <parent link="robot2_link_5"/>
    <child link="robot2_link_6"/>
    <!-- TODO The 0.03m offset are most likely caused by the mesh file (Issue 15)-->
    <origin rpy="0.0 0.0 0.0" xyz="0.0 0 0.119"/>
    <axis xyz="0 0 1"/>
    <limit effort="330.0" lower="-3.12413936106985" upper="3.12413936106985" velocity="0.7853981633974483"/>
  </joint>
  <link name="robot2_link_6">
    <visual>
      <geometry>
        <mesh filename="file:///home/unvrx/URCell/types/igus_rebel_description_ros2/meshes/igus_rebel/Joint4.dae"/>
      </geometry>
      <origin rpy="0 0 0" xyz="0 0 0"/>
    </visual>
    <collision>
      <geometry>
        <mesh filename="file:///home/unvrx/URCell/types/igus_rebel_description_ros2/meshes/igus_rebel_mod/Joint4.stl"/>
      </geometry>
      <origin rpy="0 0 0" xyz="0 0 0"/>
    </collision>
    <inertial>
      <mass value="0.1"/>
      <inertia ixx="0.03" ixy="0.0" ixz="0.0" iyy="0.03" iyz="0.0" izz="0.03"/>
    </inertial>
  </link>
  <!-- joint5 -->
  <joint name="robot2_joint5" type="revolute">
    <parent link="robot2_link_6"/>
    <child link="robot2_link_7"/>
    <!-- TODO The 0.03m offset are most likely caused by the mesh file (Issue 15) -->
    <origin rpy="0.0 -0.1308996938995747 0.0" xyz="0.0 0 0.17"/>
    <axis xyz="0 1 0"/>
    <limit effort="330.0" lower="-1.5271630954950381" upper="1.7889624832941877" velocity="0.7853981633974483"/>
  </joint>
  <link name="robot2_link_7">
    <visual>
      <geometry>
        <mesh filename="file:///home/unvrx/URCell/types/igus_rebel_description_ros2/meshes/igus_rebel/Joint5.dae"/>
      </geometry>
      <origin rpy="0 0 0" xyz="0 0 0"/>
    </visual>
    <collision>
      <geometry>
        <mesh filename="file:///home/unvrx/URCell/types/igus_rebel_description_ros2/meshes/igus_rebel_mod/Joint5.stl"/>
      </geometry>
      <origin rpy="0 0 0" xyz="0 0 0"/>
    </collision>
    <inertial>
      <mass value="0.1"/>
      <inertia ixx="0.03" ixy="0.0" ixz="0.0" iyy="0.03" iyz="0.0" izz="0.03"/>
    </inertial>
  </link>
  <!-- joint6 -->
  <joint name="robot2_joint6" type="revolute">
    <parent link="robot2_link_7"/>
    <child link="robot2_link_8"/>
    <origin rpy="0.0 0.0 0.0" xyz="0.0 0 0.1208"/>
    <axis xyz="0 0 1"/>
    <limit effort="330.0" lower="-3.12413936106985" upper="3.12413936106985" velocity="0.7853981633974483"/>
  </joint>
  <link name="robot2_link_8">
    <visual>
      <geometry>
        <mesh filename="file:///home/unvrx/URCell/types/igus_rebel_description_ros2/meshes/igus_rebel/Joint6.dae"/>
      </geometry>
      <origin rpy="0 0 0" xyz="0.0 0 0"/>
    </visual>
    <collision>
      <geometry>
        <mesh filename="file:///home/unvrx/URCell/types/igus_rebel_description_ros2/meshes/igus_rebel_mod/Joint6.stl"/>
      </geometry>
      <origin rpy="0 0 0" xyz="0.0 0 0"/>
    </collision>
    <inertial>
      <mass value="0.1"/>
      <inertia ixx="0.03" ixy="0.0" ixz="0.0" iyy="0.03" iyz="0.0" izz="0.03"/>
    </inertial>
  </link>
  <!-- joint7 → flange -->
  <joint name="robot2_joint7" type="fixed">
    <parent link="robot2_link_8"/>
    <child link="robot2_flange"/>
    <origin rpy="0.0 -1.5707963267948966 0.0" xyz="0.0 0 0.0012"/>
    <axis xyz="0 0 0"/>
  </joint>
  <link name="robot2_flange"/>
  <!-- ros2_control -->
  <ros2_control name="igus_rebel_6dof" type="system">
    <hardware>
      <plugin>irc_hardware/IrcRosCan</plugin>
      <param name="can_socket">can0</param>
    </hardware>
    <joint name="robot2_joint1">
      <command_interface name="position">
        <param name="min">-3.12413936106985</param>
        <param name="max">3.12413936106985</param>
      </command_interface>
    </joint>
  </ros2_control>
  <!-- world_to_base -->
  <joint name="robot2_world_to_base" type="fixed">
    <parent link="world"/>
    <child link="robot2_base_link"/>
    <origin rpy="0.0 0.0 0.0" xyz="0.0 0.0 0.0"/>
  </joint>
  <joint name="world_to_robot3" type="fixed">
    <parent link="world"/>
    <child link="robot3_base_link"/>
    <origin rpy="0 0 0" xyz="0 3 0"/>
  </joint>
  <!-- LINKS -->
  <link name="robot3_base_link"/>
  <link name="robot3_base_link_inertia">
    <visual>
      <origin rpy="0 0 3.141592653589793" xyz="0 0 0"/>
      <geometry>
        <mesh filename="file:///home/unvrx/URCell/types/ur_description/meshes/ur3/visual/base.dae"/>
      </geometry>
      <material name="LightGrey">
        <color rgba="0.7 0.7 0.7 1.0"/>
      </material>
    </visual>
    <collision>
      <origin rpy="0 0 3.141592653589793" xyz="0 0 0"/>
      <geometry>
        <mesh filename="file:///home/unvrx/URCell/types/ur_description/meshes/ur3/collision/base.stl"/>
      </geometry>
    </collision>
    <inertial>
      <mass value="2.0"/>
      <inertia ixx="0.0030531654454" ixy="0.0" ixz="0.0" iyy="0.0030531654454" iyz="0.0" izz="0.005625"/>
      <origin rpy="0 0 0" xyz="0 0 0"/>
    </inertial>
  </link>
  <link name="robot3_shoulder_link">
    <inertial>
      <mass value="2.0"/>
      <inertia ixx="0.008093166666666665" ixy="0.0" ixz="0.0" iyy="0.008093166666666665" iyz="0.0" izz="0.005625"/>
      <origin rpy="0 0 0" xyz="0.0 0.0 -0.02"/>
    </inertial>
    <visual>
      <origin rpy="0 0 3.141592653589793" xyz="0 0 0"/>
      <geometry>
        <mesh filename="file:///home/unvrx/URCell/types/ur_description/meshes/ur3/visual/shoulder.dae"/>
      </geometry>
      <material name="LightGrey">
        <color rgba="0.7 0.7 0.7 1.0"/>
      </material>
    </visual>
    <collision>
      <origin rpy="0 0 3.141592653589793" xyz="0 0 0"/>
      <geometry>
        <mesh filename="file:///home/unvrx/URCell/types/ur_description/meshes/ur3/collision/shoulder.stl"/>
      </geometry>
    </collision>
  </link>
  <link name="robot3_upper_arm_link">
    <inertial>
      <mass value="3.42"/>
      <inertia ixx="0.021728491912499998" ixy="0.0" ixz="0.0" iyy="0.021728491912499998" iyz="0.0" izz="0.00961875"/>
      <origin rpy="0 0 0" xyz="-0.11365 0.0 0.1157"/>
    </inertial>
    <visual>
      <origin rpy="1.5707963267948966 0 -1.5707963267948966" xyz="0 0 0.1198"/>
      <geometry>
        <mesh filename="file:///home/unvrx/URCell/types/ur_description/meshes/ur3/visual/upperarm.dae"/>
      </geometry>
      <material name="LightGrey">
        <color rgba="0.7 0.7 0.7 1.0"/>
      </material>
    </visual>
    <collision>
      <origin rpy="1.5707963267948966 0 -1.5707963267948966" xyz="0 0 0.1198"/>
      <geometry>
        <mesh filename="file:///home/unvrx/URCell/types/ur_description/meshes/ur3/collision/upperarm.stl"/>
      </geometry>
    </collision>
  </link>
  <link name="robot3_forearm_link">
    <inertial>
      <mass value="1.26"/>
      <inertia ixx="0.0065468090625" ixy="0.0" ixz="0.0" iyy="0.0065468090625" iyz="0.0" izz="0.00354375"/>
      <origin rpy="0 0 0" xyz="-0.16325 0.0 0.0238"/>
    </inertial>
    <visual>
      <origin rpy="1.5707963267948966 0 -1.5707963267948966" xyz="0 0 0.0275"/>
      <geometry>
        <mesh filename="file:///home/unvrx/URCell/types/ur_description/meshes/ur3/visual/forearm.dae"/>
      </geometry>
      <material name="LightGrey">
        <color rgba="0.7 0.7 0.7 1.0"/>
      </material>
    </visual>
    <collision>
      <origin rpy="1.5707963267948966 0 -1.5707963267948966" xyz="0 0 0.0275"/>
      <geometry>
        <mesh filename="file:///home/unvrx/URCell/types/ur_description/meshes/ur3/collision/forearm.stl"/>
      </geometry>
    </collision>
  </link>
  <link name="robot3_wrist_1_link">
    <inertial>
      <mass value="0.8"/>
      <inertia ixx="0.0016106414999999998" ixy="0.0" ixz="0.0" iyy="0.0016106414999999998" iyz="0.0" izz="0.00225"/>
      <origin rpy="0 0 0" xyz="0.0 -0.01 0.0"/>
    </inertial>
    <visual>
      <origin rpy="1.5707963267948966 0 0" xyz="0 0 -0.085"/>
      <geometry>
        <mesh filename="file:///home/unvrx/URCell/types/ur_description/meshes/ur3/visual/wrist1.dae"/>
      </geometry>
      <material name="LightGrey">
        <color rgba="0.7 0.7 0.7 1.0"/>
      </material>
    </visual>
    <collision>
      <origin rpy="1.5707963267948966 0 0" xyz="0 0 -0.085"/>
      <geometry>
        <mesh filename="file:///home/unvrx/URCell/types/ur_description/meshes/ur3/collision/wrist1.stl"/>
      </geometry>
    </collision>
  </link>
  <link name="robot3_wrist_2_link">
    <inertial>
      <mass value="0.8"/>
      <inertia ixx="0.0015721739999999998" ixy="0.0" ixz="0.0" iyy="0.0015721739999999998" iyz="0.0" izz="0.00225"/>
      <origin rpy="0 0 0" xyz="0.0 0.01 0.0"/>
    </inertial>
    <visual>
      <origin rpy="0 0 0" xyz="0 0 -0.083"/>
      <geometry>
        <mesh filename="file:///home/unvrx/URCell/types/ur_description/meshes/ur3/visual/wrist2.dae"/>
      </geometry>
      <material name="LightGrey">
        <color rgba="0.7 0.7 0.7 1.0"/>
      </material>
    </visual>
    <collision>
      <origin rpy="0 0 0" xyz="0 0 -0.083"/>
      <geometry>
        <mesh filename="file:///home/unvrx/URCell/types/ur_description/meshes/ur3/collision/wrist2.stl"/>
      </geometry>
    </collision>
  </link>
  <link name="robot3_wrist_3_link">
    <inertial>
      <mass value="0.35"/>
      <inertia ixx="0.00013626666666666665" ixy="0.0" ixz="0.0" iyy="0.00013626666666666665" iyz="0.0" izz="0.0001792"/>
      <origin rpy="0 0 0" xyz="0.0 0.0 -0.02"/>
    </inertial>
    <visual>
      <origin rpy="1.5707963267948966 0 0" xyz="0 -0.00255 -0.082"/>
      <geometry>
        <mesh filename="file:///home/unvrx/URCell/types/ur_description/meshes/ur3/visual/wrist3.dae"/>
      </geometry>
      <material name="LightGrey">
        <color rgba="0.7 0.7 0.7 1.0"/>
      </material>
    </visual>
    <collision>
      <origin rpy="1.5707963267948966 0 0" xyz="0 -0.00255 -0.082"/>
      <geometry>
        <mesh filename="file:///home/unvrx/URCell/types/ur_description/meshes/ur3/collision/wrist3.stl"/>
      </geometry>
    </collision>
  </link>
  <!-- JOINTS -->
  <joint name="robot3_base_link-base_link_inertia" type="fixed">
    <parent link="robot3_base_link"/>
    <child link="robot3_base_link_inertia"/>
    <origin rpy="0 0 3.141592653589793" xyz="0 0 0"/>
  </joint>
  <joint name="robot3_shoulder_pan_joint" type="revolute">
    <parent link="robot3_base_link_inertia"/>
    <child link="robot3_shoulder_link"/>
    <origin rpy="0 0 0" xyz="0 0 0.1519"/>
    <axis xyz="0 0 1"/>
    <limit effort="150.0" lower="-6.283185307179586" upper="6.283185307179586" velocity="3.141592653589793"/>
  </joint>
  <joint name="robot3_shoulder_lift_joint" type="revolute">
    <parent link="robot3_shoulder_link"/>
    <child link="robot3_upper_arm_link"/>
    <origin rpy="1.570796327 0 0" xyz="0 0 0"/>
    <axis xyz="0 0 1"/>
    <limit effort="150.0" lower="-6.283185307179586" upper="6.283185307179586" velocity="3.141592653589793"/>
  </joint>
  <joint name="robot3_elbow_joint" type="revolute">
    <parent link="robot3_upper_arm_link"/>
    <child link="robot3_forearm_link"/>
    <origin rpy="0 0 0" xyz="-0.24365 0 0"/>
    <axis xyz="0 0 1"/>
    <limit effort="150.0" lower="-3.141592653589793" upper="3.141592653589793" velocity="3.141592653589793"/>
  </joint>
  <joint name="robot3_wrist_1_joint" type="revolute">
    <parent link="robot3_forearm_link"/>
    <child link="robot3_wrist_1_link"/>
    <origin rpy="0 0 0" xyz="-0.21325 0 0.11235"/>
    <axis xyz="0 0 1"/>
    <limit effort="150.0" lower="-6.283185307179586" upper="6.283185307179586" velocity="6.283185307179586"/>
  </joint>
  <joint name="robot3_wrist_2_joint" type="revolute">
    <parent link="robot3_wrist_1_link"/>
    <child link="robot3_wrist_2_link"/>
    <origin rpy="1.570796327 0 0" xyz="0 -0.08535 -1.750557762378351e-11"/>
    <axis xyz="0 0 1"/>
    <limit effort="150.0" lower="-6.283185307179586" upper="6.283185307179586" velocity="6.283185307179586"/>
  </joint>
  <joint name="robot3_wrist_3_joint" type="revolute">
    <parent link="robot3_wrist_2_link"/>
    <child link="robot3_wrist_3_link"/>
    <origin rpy="1.570796326589793 3.141592653589793 3.141592653589793" xyz="0 0.0819 -1.679797079540562e-11"/>
    <axis xyz="0 0 1"/>
    <limit effort="150.0" lower="-6.283185307179586" upper="6.283185307179586" velocity="6.283185307179586"/>
  </joint>
</robot>
