<?xml version='1.0' encoding='utf-8'?>
<xacro:macro name="spawn_igus_rebel" params="instance xyz rpy robot_ip base_port">
  <robot name="IGUS_REBEL" xmlns:xacro="http://wiki.ros.org/xacro">
    <!--自动生成的 spawn 文件-->
    <!--机器人类型: IGUS_REBEL-->
    <!--生成时间: 2025-11-10 01:42:52-->
    <xacro:include filename="${urcell_root}/types/robots/igus_rebel/igus_rebel.xacro" />
    <link name="base_link" />
    <link name="shoulder_link" />
    <link name="upper_arm_link" />
    <link name="forearm_link" />
    <link name="wrist_1_link" />
    <link name="wrist_2_link" />
    <link name="wrist_3_link" />
    <link name="tool0" />
    <link name="soft_gripper_base_link" />
    <link name="soft_gripper_finger_link" />
    <link name="camera_link" />
    <link name="camera_optical_frame" />
    <joint name="shoulder_pan_joint" type="revolute">
      <parent link="base_link" />
      <child link="shoulder_link" />
      <origin xyz="1.000000 0.000000 0.000000 0.000000" rpy="0.000000 1.000000 0.000000 0.000000" />
      <axis xyz="0.0 0.0 1.0" />
      <limit lower="-6.283" upper="6.283" effort="80.0" velocity="3.142" />
      <dynamics damping="0.1" friction="0.05" />
    </joint><joint name="shoulder_lift_joint" type="revolute">
      <parent link="shoulder_link" />
      <child link="upper_arm_link" />
      <origin xyz="1.000000 0.000000 0.000000 0.000000" rpy="0.000000 1.000000 0.000000 0.000000" />
      <axis xyz="0.0 1.0 0.0" />
      <limit lower="-3.142" upper="3.142" effort="80.0" velocity="3.142" />
      <dynamics damping="0.1" friction="0.05" />
    </joint><joint name="elbow_joint" type="revolute">
      <parent link="upper_arm_link" />
      <child link="forearm_link" />
      <origin xyz="1.000000 0.000000 0.000000 0.000000" rpy="0.000000 1.000000 0.000000 0.000000" />
      <axis xyz="0.0 1.0 0.0" />
      <limit lower="-3.142" upper="3.142" effort="50.0" velocity="3.142" />
      <dynamics damping="0.1" friction="0.05" />
    </joint><joint name="wrist_1_joint" type="revolute">
      <parent link="forearm_link" />
      <child link="wrist_1_link" />
      <origin xyz="1.000000 0.000000 0.000000 0.000000" rpy="0.000000 1.000000 0.000000 0.000000" />
      <axis xyz="0.0 1.0 0.0" />
      <limit lower="-6.283" upper="6.283" effort="40.0" velocity="6.283" />
      <dynamics damping="0.05" friction="0.02" />
    </joint><joint name="wrist_2_joint" type="revolute">
      <parent link="wrist_1_link" />
      <child link="wrist_2_link" />
      <origin xyz="1.000000 0.000000 0.000000 0.000000" rpy="0.000000 1.000000 0.000000 0.000000" />
      <axis xyz="0.0 0.0 1.0" />
      <limit lower="-6.283" upper="6.283" effort="40.0" velocity="6.283" />
      <dynamics damping="0.05" friction="0.02" />
    </joint><joint name="wrist_3_joint" type="revolute">
      <parent link="wrist_2_link" />
      <child link="wrist_3_link" />
      <origin xyz="1.000000 0.000000 0.000000 0.000000" rpy="0.000000 1.000000 0.000000 0.000000" />
      <axis xyz="0.0 1.0 0.0" />
      <limit lower="-6.283" upper="6.283" effort="40.0" velocity="6.283" />
      <dynamics damping="0.05" friction="0.02" />
    </joint><joint name="tool0_fixed" type="fixed">
      <parent link="wrist_3_link" />
      <child link="tool0" />
      <origin xyz="1.000000 0.000000 0.000000 0.000000" rpy="0.000000 1.000000 0.000000 0.000000" />
      <axis xyz="1.0 0.0 0.0" />
    </joint><joint name="soft_gripper_mount" type="fixed">
      <parent link="tool0" />
      <child link="soft_gripper_base_link" />
      <origin xyz="1.000000 0.000000 0.000000 0.000000" rpy="0.000000 1.000000 0.000000 0.000000" />
      <axis xyz="1.0 0.0 0.0" />
    </joint><joint name="soft_gripper_finger_joint" type="prismatic">
      <parent link="soft_gripper_base_link" />
      <child link="soft_gripper_finger_link" />
      <origin xyz="1.000000 0.000000 0.000000 0.000000" rpy="0.000000 1.000000 0.000000 0.000000" />
      <axis xyz="0.0 0.0 1.0" />
      <limit lower="0.0" upper="0.02" effort="10.0" velocity="0.05" />
      <dynamics damping="0.01" friction="0.01" />
    </joint><joint name="camera_mount_joint" type="fixed">
      <parent link="tool0" />
      <child link="camera_link" />
      <origin xyz="1.000000 0.000000 0.000000 0.000000" rpy="0.000000 1.000000 0.000000 0.000000" />
      <axis xyz="1.0 0.0 0.0" />
    </joint><joint name="camera_optical_joint" type="fixed">
      <parent link="camera_link" />
      <child link="camera_optical_frame" />
      <origin xyz="1.000000 0.000000 0.000000 0.000000" rpy="0.000000 1.000000 0.000000 0.000000" />
      <axis xyz="1.0 0.0 0.0" />
    </joint><!--以下 transmission 为自动生成-->
    <transmission name="shoulder_pan_joint_trans">
      <type>transmission_interface/SimpleTransmission</type>
      <joint name="shoulder_pan_joint">
        <hardwareInterface>hardware_interface/EffortJointInterface</hardwareInterface>
      </joint><actuator name="shoulder_pan_joint_motor">
        <hardwareInterface>hardware_interface/EffortJointInterface</hardwareInterface>
        <mechanicalReduction>1</mechanicalReduction>
      </actuator>
    </transmission><transmission name="shoulder_lift_joint_trans">
      <type>transmission_interface/SimpleTransmission</type>
      <joint name="shoulder_lift_joint">
        <hardwareInterface>hardware_interface/EffortJointInterface</hardwareInterface>
      </joint><actuator name="shoulder_lift_joint_motor">
        <hardwareInterface>hardware_interface/EffortJointInterface</hardwareInterface>
        <mechanicalReduction>1</mechanicalReduction>
      </actuator>
    </transmission><transmission name="elbow_joint_trans">
      <type>transmission_interface/SimpleTransmission</type>
      <joint name="elbow_joint">
        <hardwareInterface>hardware_interface/EffortJointInterface</hardwareInterface>
      </joint><actuator name="elbow_joint_motor">
        <hardwareInterface>hardware_interface/EffortJointInterface</hardwareInterface>
        <mechanicalReduction>1</mechanicalReduction>
      </actuator>
    </transmission><transmission name="wrist_1_joint_trans">
      <type>transmission_interface/SimpleTransmission</type>
      <joint name="wrist_1_joint">
        <hardwareInterface>hardware_interface/EffortJointInterface</hardwareInterface>
      </joint><actuator name="wrist_1_joint_motor">
        <hardwareInterface>hardware_interface/EffortJointInterface</hardwareInterface>
        <mechanicalReduction>1</mechanicalReduction>
      </actuator>
    </transmission><transmission name="wrist_2_joint_trans">
      <type>transmission_interface/SimpleTransmission</type>
      <joint name="wrist_2_joint">
        <hardwareInterface>hardware_interface/EffortJointInterface</hardwareInterface>
      </joint><actuator name="wrist_2_joint_motor">
        <hardwareInterface>hardware_interface/EffortJointInterface</hardwareInterface>
        <mechanicalReduction>1</mechanicalReduction>
      </actuator>
    </transmission><transmission name="wrist_3_joint_trans">
      <type>transmission_interface/SimpleTransmission</type>
      <joint name="wrist_3_joint">
        <hardwareInterface>hardware_interface/EffortJointInterface</hardwareInterface>
      </joint><actuator name="wrist_3_joint_motor">
        <hardwareInterface>hardware_interface/EffortJointInterface</hardwareInterface>
        <mechanicalReduction>1</mechanicalReduction>
      </actuator>
    </transmission><transmission name="soft_gripper_finger_joint_trans">
      <type>transmission_interface/SimpleTransmission</type>
      <joint name="soft_gripper_finger_joint">
        <hardwareInterface>hardware_interface/EffortJointInterface</hardwareInterface>
      </joint><actuator name="soft_gripper_finger_joint_motor">
        <hardwareInterface>hardware_interface/EffortJointInterface</hardwareInterface>
        <mechanicalReduction>1</mechanicalReduction>
      </actuator>
    </transmission><gazebo>
      <plugin name="ros_control" filename="libgazebo_ros_control.so" />
    </gazebo>
  </robot>
</xacro:macro>