<?xml version='1.0' encoding='utf-8'?>
<robot name="IGUS_REBEL_6DOF" xmlns:xacro="http://wiki.ros.org/xacro">
  <!--Auto-generated full macro (with links + transmissions)-->
  <!--Robot: IGUS_REBEL_6DOF-->
  <!--Generated at: 2025-11-10 05:40:23-->
  <xacro:macro name="igus_spawn" params="ns xyz rpy">
    <link name="${ns}_base_link" />
    <link name="${ns}_camera_link" />
    <link name="${ns}_forearm_link" />
    <link name="${ns}_shoulder_link" />
    <link name="${ns}_soft_gripper_base_link" />
    <link name="${ns}_tool0" />
    <link name="${ns}_upper_arm_link" />
    <link name="${ns}_wrist_1_link" />
    <link name="${ns}_wrist_2_link" />
    <link name="${ns}_wrist_3_link" />
    <link name="world" />
    <joint name="${ns}_world_joint" type="fixed">
      <parent link="world" />
      <child link="${ns}_base_link" />
      <origin xyz="${xyz}" rpy="${rpy}" />
    </joint><joint name="${ns}_Link_base_link" type="revolute">
      <origin xyz="0 0 0" rpy="0 0 0" />
    </joint><joint name="${ns}_Link_shoulder_link" type="revolute">
      <origin xyz="0 0 0" rpy="0 0 0" />
    </joint><joint name="${ns}_Link_upper_arm_link" type="revolute">
      <origin xyz="0 0 0" rpy="0 0 0" />
    </joint><joint name="${ns}_Link_forearm_link" type="revolute">
      <origin xyz="0 0 0" rpy="0 0 0" />
    </joint><joint name="${ns}_Link_wrist_1_link" type="revolute">
      <origin xyz="0 0 0" rpy="0 0 0" />
    </joint><joint name="${ns}_Link_wrist_2_link" type="revolute">
      <origin xyz="0 0 0" rpy="0 0 0" />
    </joint><joint name="${ns}_Link_wrist_3_link" type="revolute">
      <origin xyz="0 0 0" rpy="0 0 0" />
    </joint><joint name="${ns}_Link_tool0" type="revolute">
      <origin xyz="0 0 0" rpy="0 0 0" />
    </joint><joint name="${ns}_Link_soft_gripper_base_link" type="revolute">
      <origin xyz="0 0 0" rpy="0 0 0" />
    </joint><joint name="${ns}_Link_soft_gripper_finger_link" type="revolute">
      <origin xyz="0 0 0" rpy="0 0 0" />
    </joint><joint name="${ns}_Link_camera_link" type="revolute">
      <origin xyz="0 0 0" rpy="0 0 0" />
    </joint><joint name="${ns}_Link_camera_optical_frame" type="revolute">
      <origin xyz="0 0 0" rpy="0 0 0" />
    </joint><joint name="${ns}_Joint_shoulder_pan_joint" type="revolute">
      <parent link="${ns}_base_link" />
      <origin xyz="0 0 0.089" rpy="0 0 0" />
    </joint><joint name="${ns}_Joint_shoulder_lift_joint" type="revolute">
      <parent link="${ns}_shoulder_link" />
      <origin xyz="0 0 0.089" rpy="0 0 0" />
    </joint><joint name="${ns}_Joint_elbow_joint" type="revolute">
      <parent link="${ns}_upper_arm_link" />
      <origin xyz="0 0 0.135" rpy="0 0 0" />
    </joint><joint name="${ns}_Joint_wrist_1_joint" type="revolute">
      <parent link="${ns}_forearm_link" />
      <origin xyz="0 0 0.121" rpy="0 0 0" />
    </joint><joint name="${ns}_Joint_wrist_2_joint" type="revolute">
      <parent link="${ns}_wrist_1_link" />
      <origin xyz="0 0 0.092" rpy="0 0 0" />
    </joint><joint name="${ns}_Joint_wrist_3_joint" type="revolute">
      <parent link="${ns}_wrist_2_link" />
      <origin xyz="0 0 0.083" rpy="0 0 0" />
    </joint><joint name="${ns}_Joint_tool0_fixed" type="revolute">
      <parent link="${ns}_wrist_3_link" />
      <origin xyz="0 0 0.05" rpy="0 0 0" />
    </joint><joint name="${ns}_Joint_soft_gripper_mount" type="revolute">
      <parent link="${ns}_tool0" />
      <origin xyz="0 0 0.02" rpy="0 0 0" />
    </joint><joint name="${ns}_Joint_soft_gripper_finger_joint" type="revolute">
      <parent link="${ns}_soft_gripper_base_link" />
      <origin xyz="0 0 0.03" rpy="0 0 0" />
    </joint><joint name="${ns}_Joint_camera_mount_joint" type="revolute">
      <parent link="${ns}_tool0" />
      <origin xyz="0 0 0.05" rpy="0 0 0" />
    </joint><joint name="${ns}_Joint_camera_optical_joint" type="revolute">
      <parent link="${ns}_camera_link" />
      <origin xyz="0 0 0.02" rpy="0 0 0" />
    </joint><joint name="${ns}_Joint_shoulder_pan_joint_Control" type="revolute">
      <origin xyz="0 0 0" rpy="0 0 0" />
    </joint><joint name="${ns}_Joint_shoulder_lift_joint_Control" type="revolute">
      <origin xyz="0 0 0" rpy="0 0 0" />
    </joint><joint name="${ns}_Joint_elbow_joint_Control" type="revolute">
      <origin xyz="0 0 0" rpy="0 0 0" />
    </joint><joint name="${ns}_Joint_wrist_1_joint_Control" type="revolute">
      <origin xyz="0 0 0" rpy="0 0 0" />
    </joint><joint name="${ns}_Joint_wrist_2_joint_Control" type="revolute">
      <origin xyz="0 0 0" rpy="0 0 0" />
    </joint><joint name="${ns}_Joint_wrist_3_joint_Control" type="revolute">
      <origin xyz="0 0 0" rpy="0 0 0" />
    </joint><joint name="${ns}_Joint_tool0_fixed_Control" type="revolute">
      <origin xyz="0 0 0" rpy="0 0 0" />
    </joint><joint name="${ns}_Joint_soft_gripper_mount_Control" type="revolute">
      <origin xyz="0 0 0" rpy="0 0 0" />
    </joint><joint name="${ns}_Joint_soft_gripper_finger_joint_Control" type="revolute">
      <origin xyz="0 0 0" rpy="0 0 0" />
    </joint><joint name="${ns}_Joint_camera_mount_joint_Control" type="revolute">
      <origin xyz="0 0 0" rpy="0 0 0" />
    </joint><joint name="${ns}_Joint_camera_optical_joint_Control" type="revolute">
      <origin xyz="0 0 0" rpy="0 0 0" />
    </joint><joint name="${ns}_Kinematics_shoulder_pan_joint" type="revolute">
      <origin xyz="0 0 0" rpy="0 0 0" />
    </joint><joint name="${ns}_Kinematics_shoulder_lift_joint" type="revolute">
      <origin xyz="0 0 0" rpy="0 0 0" />
    </joint><joint name="${ns}_Kinematics_elbow_joint" type="revolute">
      <origin xyz="0 0 0" rpy="0 0 0" />
    </joint><joint name="${ns}_Kinematics_wrist_1_joint" type="revolute">
      <origin xyz="0 0 0" rpy="0 0 0" />
    </joint><joint name="${ns}_Kinematics_wrist_2_joint" type="revolute">
      <origin xyz="0 0 0" rpy="0 0 0" />
    </joint><joint name="${ns}_Kinematics_wrist_3_joint" type="revolute">
      <origin xyz="0 0 0" rpy="0 0 0" />
    </joint><joint name="${ns}_Kinematics_soft_gripper_finger_joint" type="revolute">
      <origin xyz="0 0 0" rpy="0 0 0" />
    </joint><joint name="${ns}_Dynamics_base_link" type="revolute" />
    <joint name="${ns}_Dynamics_shoulder_link" type="revolute" />
    <joint name="${ns}_Dynamics_upper_arm_link" type="revolute" />
    <joint name="${ns}_Dynamics_forearm_link" type="revolute" />
    <joint name="${ns}_Dynamics_wrist_1_link" type="revolute" />
    <joint name="${ns}_Dynamics_wrist_2_link" type="revolute" />
    <joint name="${ns}_Dynamics_wrist_3_link" type="revolute" />
    <joint name="${ns}_Dynamics_tool0" type="revolute" />
    <joint name="${ns}_Dynamics_soft_gripper_base_link" type="revolute" />
    <joint name="${ns}_Dynamics_soft_gripper_finger_link" type="revolute" />
    <joint name="${ns}_Dynamics_camera_link" type="revolute" />
    <joint name="${ns}_Dynamics_camera_optical_frame" type="revolute" />
    <joint name="${ns}_Joint_shoulder_pan_joint_Safety" type="revolute">
      <origin xyz="0 0 0" rpy="0 0 0" />
    </joint><joint name="${ns}_Joint_shoulder_lift_joint_Safety" type="revolute">
      <origin xyz="0 0 0" rpy="0 0 0" />
    </joint><joint name="${ns}_Joint_elbow_joint_Safety" type="revolute">
      <origin xyz="0 0 0" rpy="0 0 0" />
    </joint><joint name="${ns}_Joint_wrist_1_joint_Safety" type="revolute">
      <origin xyz="0 0 0" rpy="0 0 0" />
    </joint><joint name="${ns}_Joint_wrist_2_joint_Safety" type="revolute">
      <origin xyz="0 0 0" rpy="0 0 0" />
    </joint><joint name="${ns}_Joint_wrist_3_joint_Safety" type="revolute">
      <origin xyz="0 0 0" rpy="0 0 0" />
    </joint><joint name="${ns}_Joint_soft_gripper_finger_joint_Safety" type="revolute">
      <origin xyz="0 0 0" rpy="0 0 0" />
    </joint><joint name="${ns}_Visual_base_link_0" type="revolute">
      <origin xyz="0 0 0" rpy="0 0 0" />
    </joint><joint name="${ns}_Visual_base_link_1" type="revolute">
      <origin xyz="0 0 0" rpy="0 0 0" />
    </joint><joint name="${ns}_Visual_shoulder_link_0" type="revolute">
      <origin xyz="0 0 0" rpy="0 0 0" />
    </joint><joint name="${ns}_Visual_shoulder_link_1" type="revolute">
      <origin xyz="0 0 0" rpy="0 0 0" />
    </joint><joint name="${ns}_Visual_upper_arm_link_0" type="revolute">
      <origin xyz="0 0 0" rpy="0 0 0" />
    </joint><joint name="${ns}_Visual_upper_arm_link_1" type="revolute">
      <origin xyz="0 0 0" rpy="0 0 0" />
    </joint><joint name="${ns}_Visual_forearm_link_0" type="revolute">
      <origin xyz="0 0 0" rpy="0 0 0" />
    </joint><joint name="${ns}_Visual_forearm_link_1" type="revolute">
      <origin xyz="0 0 0" rpy="0 0 0" />
    </joint><joint name="${ns}_Visual_wrist_1_link_0" type="revolute">
      <origin xyz="0 0 0" rpy="0 0 0" />
    </joint><joint name="${ns}_Visual_wrist_1_link_1" type="revolute">
      <origin xyz="0 0 0" rpy="0 0 0" />
    </joint><joint name="${ns}_Visual_wrist_2_link_0" type="revolute">
      <origin xyz="0 0 0" rpy="0 0 0" />
    </joint><joint name="${ns}_Visual_wrist_2_link_1" type="revolute">
      <origin xyz="0 0 0" rpy="0 0 0" />
    </joint><joint name="${ns}_Visual_wrist_3_link_0" type="revolute">
      <origin xyz="0 0 0" rpy="0 0 0" />
    </joint><joint name="${ns}_Visual_wrist_3_link_1" type="revolute">
      <origin xyz="0 0 0" rpy="0 0 0" />
    </joint><joint name="${ns}_Visual_tool0_0" type="revolute">
      <origin xyz="0 0 0" rpy="0 0 0" />
    </joint><joint name="${ns}_Visual_tool0_1" type="revolute">
      <origin xyz="0 0 0" rpy="0 0 0" />
    </joint><joint name="${ns}_Visual_soft_gripper_base_link_0" type="revolute">
      <origin xyz="0 0 0" rpy="0 0 0" />
    </joint><joint name="${ns}_Visual_soft_gripper_base_link_1" type="revolute">
      <origin xyz="0 0 0" rpy="0 0 0" />
    </joint><joint name="${ns}_Visual_soft_gripper_finger_link_0" type="revolute">
      <origin xyz="0 0 0" rpy="0 0 0" />
    </joint><joint name="${ns}_Visual_soft_gripper_finger_link_1" type="revolute">
      <origin xyz="0 0 0" rpy="0 0 0" />
    </joint><joint name="${ns}_Visual_camera_link_0" type="revolute">
      <origin xyz="0 0 0" rpy="0 0 0" />
    </joint><joint name="${ns}_Visual_camera_link_1" type="revolute">
      <origin xyz="0 0 0" rpy="0 0 0" />
    </joint><joint name="${ns}_Visual_camera_optical_frame_0" type="revolute">
      <origin xyz="0 0 0" rpy="0 0 0" />
    </joint>
  </xacro:macro><!--Auto-generated transmission blocks-->
  <transmission name="${ns}_Link_base_link_trans">
    <type>transmission_interface/SimpleTransmission</type>
    <joint name="${ns}_Link_base_link">
      <hardwareInterface>hardware_interface/PositionJointInterface</hardwareInterface>
    </joint><actuator name="${ns}_Link_base_link_motor">
      <hardwareInterface>hardware_interface/PositionJointInterface</hardwareInterface>
      <mechanicalReduction>1</mechanicalReduction>
    </actuator>
  </transmission><transmission name="${ns}_Link_shoulder_link_trans">
    <type>transmission_interface/SimpleTransmission</type>
    <joint name="${ns}_Link_shoulder_link">
      <hardwareInterface>hardware_interface/PositionJointInterface</hardwareInterface>
    </joint><actuator name="${ns}_Link_shoulder_link_motor">
      <hardwareInterface>hardware_interface/PositionJointInterface</hardwareInterface>
      <mechanicalReduction>1</mechanicalReduction>
    </actuator>
  </transmission><transmission name="${ns}_Link_upper_arm_link_trans">
    <type>transmission_interface/SimpleTransmission</type>
    <joint name="${ns}_Link_upper_arm_link">
      <hardwareInterface>hardware_interface/PositionJointInterface</hardwareInterface>
    </joint><actuator name="${ns}_Link_upper_arm_link_motor">
      <hardwareInterface>hardware_interface/PositionJointInterface</hardwareInterface>
      <mechanicalReduction>1</mechanicalReduction>
    </actuator>
  </transmission><transmission name="${ns}_Link_forearm_link_trans">
    <type>transmission_interface/SimpleTransmission</type>
    <joint name="${ns}_Link_forearm_link">
      <hardwareInterface>hardware_interface/PositionJointInterface</hardwareInterface>
    </joint><actuator name="${ns}_Link_forearm_link_motor">
      <hardwareInterface>hardware_interface/PositionJointInterface</hardwareInterface>
      <mechanicalReduction>1</mechanicalReduction>
    </actuator>
  </transmission><transmission name="${ns}_Link_wrist_1_link_trans">
    <type>transmission_interface/SimpleTransmission</type>
    <joint name="${ns}_Link_wrist_1_link">
      <hardwareInterface>hardware_interface/PositionJointInterface</hardwareInterface>
    </joint><actuator name="${ns}_Link_wrist_1_link_motor">
      <hardwareInterface>hardware_interface/PositionJointInterface</hardwareInterface>
      <mechanicalReduction>1</mechanicalReduction>
    </actuator>
  </transmission><transmission name="${ns}_Link_wrist_2_link_trans">
    <type>transmission_interface/SimpleTransmission</type>
    <joint name="${ns}_Link_wrist_2_link">
      <hardwareInterface>hardware_interface/PositionJointInterface</hardwareInterface>
    </joint><actuator name="${ns}_Link_wrist_2_link_motor">
      <hardwareInterface>hardware_interface/PositionJointInterface</hardwareInterface>
      <mechanicalReduction>1</mechanicalReduction>
    </actuator>
  </transmission><transmission name="${ns}_Link_wrist_3_link_trans">
    <type>transmission_interface/SimpleTransmission</type>
    <joint name="${ns}_Link_wrist_3_link">
      <hardwareInterface>hardware_interface/PositionJointInterface</hardwareInterface>
    </joint><actuator name="${ns}_Link_wrist_3_link_motor">
      <hardwareInterface>hardware_interface/PositionJointInterface</hardwareInterface>
      <mechanicalReduction>1</mechanicalReduction>
    </actuator>
  </transmission><transmission name="${ns}_Link_tool0_trans">
    <type>transmission_interface/SimpleTransmission</type>
    <joint name="${ns}_Link_tool0">
      <hardwareInterface>hardware_interface/PositionJointInterface</hardwareInterface>
    </joint><actuator name="${ns}_Link_tool0_motor">
      <hardwareInterface>hardware_interface/PositionJointInterface</hardwareInterface>
      <mechanicalReduction>1</mechanicalReduction>
    </actuator>
  </transmission><transmission name="${ns}_Link_soft_gripper_base_link_trans">
    <type>transmission_interface/SimpleTransmission</type>
    <joint name="${ns}_Link_soft_gripper_base_link">
      <hardwareInterface>hardware_interface/PositionJointInterface</hardwareInterface>
    </joint><actuator name="${ns}_Link_soft_gripper_base_link_motor">
      <hardwareInterface>hardware_interface/PositionJointInterface</hardwareInterface>
      <mechanicalReduction>1</mechanicalReduction>
    </actuator>
  </transmission><transmission name="${ns}_Link_soft_gripper_finger_link_trans">
    <type>transmission_interface/SimpleTransmission</type>
    <joint name="${ns}_Link_soft_gripper_finger_link">
      <hardwareInterface>hardware_interface/PositionJointInterface</hardwareInterface>
    </joint><actuator name="${ns}_Link_soft_gripper_finger_link_motor">
      <hardwareInterface>hardware_interface/PositionJointInterface</hardwareInterface>
      <mechanicalReduction>1</mechanicalReduction>
    </actuator>
  </transmission><transmission name="${ns}_Link_camera_link_trans">
    <type>transmission_interface/SimpleTransmission</type>
    <joint name="${ns}_Link_camera_link">
      <hardwareInterface>hardware_interface/PositionJointInterface</hardwareInterface>
    </joint><actuator name="${ns}_Link_camera_link_motor">
      <hardwareInterface>hardware_interface/PositionJointInterface</hardwareInterface>
      <mechanicalReduction>1</mechanicalReduction>
    </actuator>
  </transmission><transmission name="${ns}_Link_camera_optical_frame_trans">
    <type>transmission_interface/SimpleTransmission</type>
    <joint name="${ns}_Link_camera_optical_frame">
      <hardwareInterface>hardware_interface/PositionJointInterface</hardwareInterface>
    </joint><actuator name="${ns}_Link_camera_optical_frame_motor">
      <hardwareInterface>hardware_interface/PositionJointInterface</hardwareInterface>
      <mechanicalReduction>1</mechanicalReduction>
    </actuator>
  </transmission><transmission name="${ns}_Joint_shoulder_pan_joint_trans">
    <type>transmission_interface/SimpleTransmission</type>
    <joint name="${ns}_Joint_shoulder_pan_joint">
      <hardwareInterface>hardware_interface/PositionJointInterface</hardwareInterface>
    </joint><actuator name="${ns}_Joint_shoulder_pan_joint_motor">
      <hardwareInterface>hardware_interface/PositionJointInterface</hardwareInterface>
      <mechanicalReduction>1</mechanicalReduction>
    </actuator>
  </transmission><transmission name="${ns}_Joint_shoulder_lift_joint_trans">
    <type>transmission_interface/SimpleTransmission</type>
    <joint name="${ns}_Joint_shoulder_lift_joint">
      <hardwareInterface>hardware_interface/PositionJointInterface</hardwareInterface>
    </joint><actuator name="${ns}_Joint_shoulder_lift_joint_motor">
      <hardwareInterface>hardware_interface/PositionJointInterface</hardwareInterface>
      <mechanicalReduction>1</mechanicalReduction>
    </actuator>
  </transmission><transmission name="${ns}_Joint_elbow_joint_trans">
    <type>transmission_interface/SimpleTransmission</type>
    <joint name="${ns}_Joint_elbow_joint">
      <hardwareInterface>hardware_interface/PositionJointInterface</hardwareInterface>
    </joint><actuator name="${ns}_Joint_elbow_joint_motor">
      <hardwareInterface>hardware_interface/PositionJointInterface</hardwareInterface>
      <mechanicalReduction>1</mechanicalReduction>
    </actuator>
  </transmission><transmission name="${ns}_Joint_wrist_1_joint_trans">
    <type>transmission_interface/SimpleTransmission</type>
    <joint name="${ns}_Joint_wrist_1_joint">
      <hardwareInterface>hardware_interface/PositionJointInterface</hardwareInterface>
    </joint><actuator name="${ns}_Joint_wrist_1_joint_motor">
      <hardwareInterface>hardware_interface/PositionJointInterface</hardwareInterface>
      <mechanicalReduction>1</mechanicalReduction>
    </actuator>
  </transmission><transmission name="${ns}_Joint_wrist_2_joint_trans">
    <type>transmission_interface/SimpleTransmission</type>
    <joint name="${ns}_Joint_wrist_2_joint">
      <hardwareInterface>hardware_interface/PositionJointInterface</hardwareInterface>
    </joint><actuator name="${ns}_Joint_wrist_2_joint_motor">
      <hardwareInterface>hardware_interface/PositionJointInterface</hardwareInterface>
      <mechanicalReduction>1</mechanicalReduction>
    </actuator>
  </transmission><transmission name="${ns}_Joint_wrist_3_joint_trans">
    <type>transmission_interface/SimpleTransmission</type>
    <joint name="${ns}_Joint_wrist_3_joint">
      <hardwareInterface>hardware_interface/PositionJointInterface</hardwareInterface>
    </joint><actuator name="${ns}_Joint_wrist_3_joint_motor">
      <hardwareInterface>hardware_interface/PositionJointInterface</hardwareInterface>
      <mechanicalReduction>1</mechanicalReduction>
    </actuator>
  </transmission><transmission name="${ns}_Joint_tool0_fixed_trans">
    <type>transmission_interface/SimpleTransmission</type>
    <joint name="${ns}_Joint_tool0_fixed">
      <hardwareInterface>hardware_interface/PositionJointInterface</hardwareInterface>
    </joint><actuator name="${ns}_Joint_tool0_fixed_motor">
      <hardwareInterface>hardware_interface/PositionJointInterface</hardwareInterface>
      <mechanicalReduction>1</mechanicalReduction>
    </actuator>
  </transmission><transmission name="${ns}_Joint_soft_gripper_mount_trans">
    <type>transmission_interface/SimpleTransmission</type>
    <joint name="${ns}_Joint_soft_gripper_mount">
      <hardwareInterface>hardware_interface/PositionJointInterface</hardwareInterface>
    </joint><actuator name="${ns}_Joint_soft_gripper_mount_motor">
      <hardwareInterface>hardware_interface/PositionJointInterface</hardwareInterface>
      <mechanicalReduction>1</mechanicalReduction>
    </actuator>
  </transmission><transmission name="${ns}_Joint_soft_gripper_finger_joint_trans">
    <type>transmission_interface/SimpleTransmission</type>
    <joint name="${ns}_Joint_soft_gripper_finger_joint">
      <hardwareInterface>hardware_interface/PositionJointInterface</hardwareInterface>
    </joint><actuator name="${ns}_Joint_soft_gripper_finger_joint_motor">
      <hardwareInterface>hardware_interface/PositionJointInterface</hardwareInterface>
      <mechanicalReduction>1</mechanicalReduction>
    </actuator>
  </transmission><transmission name="${ns}_Joint_camera_mount_joint_trans">
    <type>transmission_interface/SimpleTransmission</type>
    <joint name="${ns}_Joint_camera_mount_joint">
      <hardwareInterface>hardware_interface/PositionJointInterface</hardwareInterface>
    </joint><actuator name="${ns}_Joint_camera_mount_joint_motor">
      <hardwareInterface>hardware_interface/PositionJointInterface</hardwareInterface>
      <mechanicalReduction>1</mechanicalReduction>
    </actuator>
  </transmission><transmission name="${ns}_Joint_camera_optical_joint_trans">
    <type>transmission_interface/SimpleTransmission</type>
    <joint name="${ns}_Joint_camera_optical_joint">
      <hardwareInterface>hardware_interface/PositionJointInterface</hardwareInterface>
    </joint><actuator name="${ns}_Joint_camera_optical_joint_motor">
      <hardwareInterface>hardware_interface/PositionJointInterface</hardwareInterface>
      <mechanicalReduction>1</mechanicalReduction>
    </actuator>
  </transmission><transmission name="${ns}_Joint_shoulder_pan_joint_Control_trans">
    <type>transmission_interface/SimpleTransmission</type>
    <joint name="${ns}_Joint_shoulder_pan_joint_Control">
      <hardwareInterface>hardware_interface/PositionJointInterface</hardwareInterface>
    </joint><actuator name="${ns}_Joint_shoulder_pan_joint_Control_motor">
      <hardwareInterface>hardware_interface/PositionJointInterface</hardwareInterface>
      <mechanicalReduction>1</mechanicalReduction>
    </actuator>
  </transmission><transmission name="${ns}_Joint_shoulder_lift_joint_Control_trans">
    <type>transmission_interface/SimpleTransmission</type>
    <joint name="${ns}_Joint_shoulder_lift_joint_Control">
      <hardwareInterface>hardware_interface/PositionJointInterface</hardwareInterface>
    </joint><actuator name="${ns}_Joint_shoulder_lift_joint_Control_motor">
      <hardwareInterface>hardware_interface/PositionJointInterface</hardwareInterface>
      <mechanicalReduction>1</mechanicalReduction>
    </actuator>
  </transmission><transmission name="${ns}_Joint_elbow_joint_Control_trans">
    <type>transmission_interface/SimpleTransmission</type>
    <joint name="${ns}_Joint_elbow_joint_Control">
      <hardwareInterface>hardware_interface/PositionJointInterface</hardwareInterface>
    </joint><actuator name="${ns}_Joint_elbow_joint_Control_motor">
      <hardwareInterface>hardware_interface/PositionJointInterface</hardwareInterface>
      <mechanicalReduction>1</mechanicalReduction>
    </actuator>
  </transmission><transmission name="${ns}_Joint_wrist_1_joint_Control_trans">
    <type>transmission_interface/SimpleTransmission</type>
    <joint name="${ns}_Joint_wrist_1_joint_Control">
      <hardwareInterface>hardware_interface/PositionJointInterface</hardwareInterface>
    </joint><actuator name="${ns}_Joint_wrist_1_joint_Control_motor">
      <hardwareInterface>hardware_interface/PositionJointInterface</hardwareInterface>
      <mechanicalReduction>1</mechanicalReduction>
    </actuator>
  </transmission><transmission name="${ns}_Joint_wrist_2_joint_Control_trans">
    <type>transmission_interface/SimpleTransmission</type>
    <joint name="${ns}_Joint_wrist_2_joint_Control">
      <hardwareInterface>hardware_interface/PositionJointInterface</hardwareInterface>
    </joint><actuator name="${ns}_Joint_wrist_2_joint_Control_motor">
      <hardwareInterface>hardware_interface/PositionJointInterface</hardwareInterface>
      <mechanicalReduction>1</mechanicalReduction>
    </actuator>
  </transmission><transmission name="${ns}_Joint_wrist_3_joint_Control_trans">
    <type>transmission_interface/SimpleTransmission</type>
    <joint name="${ns}_Joint_wrist_3_joint_Control">
      <hardwareInterface>hardware_interface/PositionJointInterface</hardwareInterface>
    </joint><actuator name="${ns}_Joint_wrist_3_joint_Control_motor">
      <hardwareInterface>hardware_interface/PositionJointInterface</hardwareInterface>
      <mechanicalReduction>1</mechanicalReduction>
    </actuator>
  </transmission><transmission name="${ns}_Joint_tool0_fixed_Control_trans">
    <type>transmission_interface/SimpleTransmission</type>
    <joint name="${ns}_Joint_tool0_fixed_Control">
      <hardwareInterface>hardware_interface/PositionJointInterface</hardwareInterface>
    </joint><actuator name="${ns}_Joint_tool0_fixed_Control_motor">
      <hardwareInterface>hardware_interface/PositionJointInterface</hardwareInterface>
      <mechanicalReduction>1</mechanicalReduction>
    </actuator>
  </transmission><transmission name="${ns}_Joint_soft_gripper_mount_Control_trans">
    <type>transmission_interface/SimpleTransmission</type>
    <joint name="${ns}_Joint_soft_gripper_mount_Control">
      <hardwareInterface>hardware_interface/PositionJointInterface</hardwareInterface>
    </joint><actuator name="${ns}_Joint_soft_gripper_mount_Control_motor">
      <hardwareInterface>hardware_interface/PositionJointInterface</hardwareInterface>
      <mechanicalReduction>1</mechanicalReduction>
    </actuator>
  </transmission><transmission name="${ns}_Joint_soft_gripper_finger_joint_Control_trans">
    <type>transmission_interface/SimpleTransmission</type>
    <joint name="${ns}_Joint_soft_gripper_finger_joint_Control">
      <hardwareInterface>hardware_interface/PositionJointInterface</hardwareInterface>
    </joint><actuator name="${ns}_Joint_soft_gripper_finger_joint_Control_motor">
      <hardwareInterface>hardware_interface/PositionJointInterface</hardwareInterface>
      <mechanicalReduction>1</mechanicalReduction>
    </actuator>
  </transmission><transmission name="${ns}_Joint_camera_mount_joint_Control_trans">
    <type>transmission_interface/SimpleTransmission</type>
    <joint name="${ns}_Joint_camera_mount_joint_Control">
      <hardwareInterface>hardware_interface/PositionJointInterface</hardwareInterface>
    </joint><actuator name="${ns}_Joint_camera_mount_joint_Control_motor">
      <hardwareInterface>hardware_interface/PositionJointInterface</hardwareInterface>
      <mechanicalReduction>1</mechanicalReduction>
    </actuator>
  </transmission><transmission name="${ns}_Joint_camera_optical_joint_Control_trans">
    <type>transmission_interface/SimpleTransmission</type>
    <joint name="${ns}_Joint_camera_optical_joint_Control">
      <hardwareInterface>hardware_interface/PositionJointInterface</hardwareInterface>
    </joint><actuator name="${ns}_Joint_camera_optical_joint_Control_motor">
      <hardwareInterface>hardware_interface/PositionJointInterface</hardwareInterface>
      <mechanicalReduction>1</mechanicalReduction>
    </actuator>
  </transmission><transmission name="${ns}_Kinematics_shoulder_pan_joint_trans">
    <type>transmission_interface/SimpleTransmission</type>
    <joint name="${ns}_Kinematics_shoulder_pan_joint">
      <hardwareInterface>hardware_interface/PositionJointInterface</hardwareInterface>
    </joint><actuator name="${ns}_Kinematics_shoulder_pan_joint_motor">
      <hardwareInterface>hardware_interface/PositionJointInterface</hardwareInterface>
      <mechanicalReduction>1</mechanicalReduction>
    </actuator>
  </transmission><transmission name="${ns}_Kinematics_shoulder_lift_joint_trans">
    <type>transmission_interface/SimpleTransmission</type>
    <joint name="${ns}_Kinematics_shoulder_lift_joint">
      <hardwareInterface>hardware_interface/PositionJointInterface</hardwareInterface>
    </joint><actuator name="${ns}_Kinematics_shoulder_lift_joint_motor">
      <hardwareInterface>hardware_interface/PositionJointInterface</hardwareInterface>
      <mechanicalReduction>1</mechanicalReduction>
    </actuator>
  </transmission><transmission name="${ns}_Kinematics_elbow_joint_trans">
    <type>transmission_interface/SimpleTransmission</type>
    <joint name="${ns}_Kinematics_elbow_joint">
      <hardwareInterface>hardware_interface/PositionJointInterface</hardwareInterface>
    </joint><actuator name="${ns}_Kinematics_elbow_joint_motor">
      <hardwareInterface>hardware_interface/PositionJointInterface</hardwareInterface>
      <mechanicalReduction>1</mechanicalReduction>
    </actuator>
  </transmission><transmission name="${ns}_Kinematics_wrist_1_joint_trans">
    <type>transmission_interface/SimpleTransmission</type>
    <joint name="${ns}_Kinematics_wrist_1_joint">
      <hardwareInterface>hardware_interface/PositionJointInterface</hardwareInterface>
    </joint><actuator name="${ns}_Kinematics_wrist_1_joint_motor">
      <hardwareInterface>hardware_interface/PositionJointInterface</hardwareInterface>
      <mechanicalReduction>1</mechanicalReduction>
    </actuator>
  </transmission><transmission name="${ns}_Kinematics_wrist_2_joint_trans">
    <type>transmission_interface/SimpleTransmission</type>
    <joint name="${ns}_Kinematics_wrist_2_joint">
      <hardwareInterface>hardware_interface/PositionJointInterface</hardwareInterface>
    </joint><actuator name="${ns}_Kinematics_wrist_2_joint_motor">
      <hardwareInterface>hardware_interface/PositionJointInterface</hardwareInterface>
      <mechanicalReduction>1</mechanicalReduction>
    </actuator>
  </transmission><transmission name="${ns}_Kinematics_wrist_3_joint_trans">
    <type>transmission_interface/SimpleTransmission</type>
    <joint name="${ns}_Kinematics_wrist_3_joint">
      <hardwareInterface>hardware_interface/PositionJointInterface</hardwareInterface>
    </joint><actuator name="${ns}_Kinematics_wrist_3_joint_motor">
      <hardwareInterface>hardware_interface/PositionJointInterface</hardwareInterface>
      <mechanicalReduction>1</mechanicalReduction>
    </actuator>
  </transmission><transmission name="${ns}_Kinematics_soft_gripper_finger_joint_trans">
    <type>transmission_interface/SimpleTransmission</type>
    <joint name="${ns}_Kinematics_soft_gripper_finger_joint">
      <hardwareInterface>hardware_interface/PositionJointInterface</hardwareInterface>
    </joint><actuator name="${ns}_Kinematics_soft_gripper_finger_joint_motor">
      <hardwareInterface>hardware_interface/PositionJointInterface</hardwareInterface>
      <mechanicalReduction>1</mechanicalReduction>
    </actuator>
  </transmission><transmission name="${ns}_Dynamics_base_link_trans">
    <type>transmission_interface/SimpleTransmission</type>
    <joint name="${ns}_Dynamics_base_link">
      <hardwareInterface>hardware_interface/PositionJointInterface</hardwareInterface>
    </joint><actuator name="${ns}_Dynamics_base_link_motor">
      <hardwareInterface>hardware_interface/PositionJointInterface</hardwareInterface>
      <mechanicalReduction>1</mechanicalReduction>
    </actuator>
  </transmission><transmission name="${ns}_Dynamics_shoulder_link_trans">
    <type>transmission_interface/SimpleTransmission</type>
    <joint name="${ns}_Dynamics_shoulder_link">
      <hardwareInterface>hardware_interface/PositionJointInterface</hardwareInterface>
    </joint><actuator name="${ns}_Dynamics_shoulder_link_motor">
      <hardwareInterface>hardware_interface/PositionJointInterface</hardwareInterface>
      <mechanicalReduction>1</mechanicalReduction>
    </actuator>
  </transmission><transmission name="${ns}_Dynamics_upper_arm_link_trans">
    <type>transmission_interface/SimpleTransmission</type>
    <joint name="${ns}_Dynamics_upper_arm_link">
      <hardwareInterface>hardware_interface/PositionJointInterface</hardwareInterface>
    </joint><actuator name="${ns}_Dynamics_upper_arm_link_motor">
      <hardwareInterface>hardware_interface/PositionJointInterface</hardwareInterface>
      <mechanicalReduction>1</mechanicalReduction>
    </actuator>
  </transmission><transmission name="${ns}_Dynamics_forearm_link_trans">
    <type>transmission_interface/SimpleTransmission</type>
    <joint name="${ns}_Dynamics_forearm_link">
      <hardwareInterface>hardware_interface/PositionJointInterface</hardwareInterface>
    </joint><actuator name="${ns}_Dynamics_forearm_link_motor">
      <hardwareInterface>hardware_interface/PositionJointInterface</hardwareInterface>
      <mechanicalReduction>1</mechanicalReduction>
    </actuator>
  </transmission><transmission name="${ns}_Dynamics_wrist_1_link_trans">
    <type>transmission_interface/SimpleTransmission</type>
    <joint name="${ns}_Dynamics_wrist_1_link">
      <hardwareInterface>hardware_interface/PositionJointInterface</hardwareInterface>
    </joint><actuator name="${ns}_Dynamics_wrist_1_link_motor">
      <hardwareInterface>hardware_interface/PositionJointInterface</hardwareInterface>
      <mechanicalReduction>1</mechanicalReduction>
    </actuator>
  </transmission><transmission name="${ns}_Dynamics_wrist_2_link_trans">
    <type>transmission_interface/SimpleTransmission</type>
    <joint name="${ns}_Dynamics_wrist_2_link">
      <hardwareInterface>hardware_interface/PositionJointInterface</hardwareInterface>
    </joint><actuator name="${ns}_Dynamics_wrist_2_link_motor">
      <hardwareInterface>hardware_interface/PositionJointInterface</hardwareInterface>
      <mechanicalReduction>1</mechanicalReduction>
    </actuator>
  </transmission><transmission name="${ns}_Dynamics_wrist_3_link_trans">
    <type>transmission_interface/SimpleTransmission</type>
    <joint name="${ns}_Dynamics_wrist_3_link">
      <hardwareInterface>hardware_interface/PositionJointInterface</hardwareInterface>
    </joint><actuator name="${ns}_Dynamics_wrist_3_link_motor">
      <hardwareInterface>hardware_interface/PositionJointInterface</hardwareInterface>
      <mechanicalReduction>1</mechanicalReduction>
    </actuator>
  </transmission><transmission name="${ns}_Dynamics_tool0_trans">
    <type>transmission_interface/SimpleTransmission</type>
    <joint name="${ns}_Dynamics_tool0">
      <hardwareInterface>hardware_interface/PositionJointInterface</hardwareInterface>
    </joint><actuator name="${ns}_Dynamics_tool0_motor">
      <hardwareInterface>hardware_interface/PositionJointInterface</hardwareInterface>
      <mechanicalReduction>1</mechanicalReduction>
    </actuator>
  </transmission><transmission name="${ns}_Dynamics_soft_gripper_base_link_trans">
    <type>transmission_interface/SimpleTransmission</type>
    <joint name="${ns}_Dynamics_soft_gripper_base_link">
      <hardwareInterface>hardware_interface/PositionJointInterface</hardwareInterface>
    </joint><actuator name="${ns}_Dynamics_soft_gripper_base_link_motor">
      <hardwareInterface>hardware_interface/PositionJointInterface</hardwareInterface>
      <mechanicalReduction>1</mechanicalReduction>
    </actuator>
  </transmission><transmission name="${ns}_Dynamics_soft_gripper_finger_link_trans">
    <type>transmission_interface/SimpleTransmission</type>
    <joint name="${ns}_Dynamics_soft_gripper_finger_link">
      <hardwareInterface>hardware_interface/PositionJointInterface</hardwareInterface>
    </joint><actuator name="${ns}_Dynamics_soft_gripper_finger_link_motor">
      <hardwareInterface>hardware_interface/PositionJointInterface</hardwareInterface>
      <mechanicalReduction>1</mechanicalReduction>
    </actuator>
  </transmission><transmission name="${ns}_Dynamics_camera_link_trans">
    <type>transmission_interface/SimpleTransmission</type>
    <joint name="${ns}_Dynamics_camera_link">
      <hardwareInterface>hardware_interface/PositionJointInterface</hardwareInterface>
    </joint><actuator name="${ns}_Dynamics_camera_link_motor">
      <hardwareInterface>hardware_interface/PositionJointInterface</hardwareInterface>
      <mechanicalReduction>1</mechanicalReduction>
    </actuator>
  </transmission><transmission name="${ns}_Dynamics_camera_optical_frame_trans">
    <type>transmission_interface/SimpleTransmission</type>
    <joint name="${ns}_Dynamics_camera_optical_frame">
      <hardwareInterface>hardware_interface/PositionJointInterface</hardwareInterface>
    </joint><actuator name="${ns}_Dynamics_camera_optical_frame_motor">
      <hardwareInterface>hardware_interface/PositionJointInterface</hardwareInterface>
      <mechanicalReduction>1</mechanicalReduction>
    </actuator>
  </transmission><transmission name="${ns}_Joint_shoulder_pan_joint_Safety_trans">
    <type>transmission_interface/SimpleTransmission</type>
    <joint name="${ns}_Joint_shoulder_pan_joint_Safety">
      <hardwareInterface>hardware_interface/PositionJointInterface</hardwareInterface>
    </joint><actuator name="${ns}_Joint_shoulder_pan_joint_Safety_motor">
      <hardwareInterface>hardware_interface/PositionJointInterface</hardwareInterface>
      <mechanicalReduction>1</mechanicalReduction>
    </actuator>
  </transmission><transmission name="${ns}_Joint_shoulder_lift_joint_Safety_trans">
    <type>transmission_interface/SimpleTransmission</type>
    <joint name="${ns}_Joint_shoulder_lift_joint_Safety">
      <hardwareInterface>hardware_interface/PositionJointInterface</hardwareInterface>
    </joint><actuator name="${ns}_Joint_shoulder_lift_joint_Safety_motor">
      <hardwareInterface>hardware_interface/PositionJointInterface</hardwareInterface>
      <mechanicalReduction>1</mechanicalReduction>
    </actuator>
  </transmission><transmission name="${ns}_Joint_elbow_joint_Safety_trans">
    <type>transmission_interface/SimpleTransmission</type>
    <joint name="${ns}_Joint_elbow_joint_Safety">
      <hardwareInterface>hardware_interface/PositionJointInterface</hardwareInterface>
    </joint><actuator name="${ns}_Joint_elbow_joint_Safety_motor">
      <hardwareInterface>hardware_interface/PositionJointInterface</hardwareInterface>
      <mechanicalReduction>1</mechanicalReduction>
    </actuator>
  </transmission><transmission name="${ns}_Joint_wrist_1_joint_Safety_trans">
    <type>transmission_interface/SimpleTransmission</type>
    <joint name="${ns}_Joint_wrist_1_joint_Safety">
      <hardwareInterface>hardware_interface/PositionJointInterface</hardwareInterface>
    </joint><actuator name="${ns}_Joint_wrist_1_joint_Safety_motor">
      <hardwareInterface>hardware_interface/PositionJointInterface</hardwareInterface>
      <mechanicalReduction>1</mechanicalReduction>
    </actuator>
  </transmission><transmission name="${ns}_Joint_wrist_2_joint_Safety_trans">
    <type>transmission_interface/SimpleTransmission</type>
    <joint name="${ns}_Joint_wrist_2_joint_Safety">
      <hardwareInterface>hardware_interface/PositionJointInterface</hardwareInterface>
    </joint><actuator name="${ns}_Joint_wrist_2_joint_Safety_motor">
      <hardwareInterface>hardware_interface/PositionJointInterface</hardwareInterface>
      <mechanicalReduction>1</mechanicalReduction>
    </actuator>
  </transmission><transmission name="${ns}_Joint_wrist_3_joint_Safety_trans">
    <type>transmission_interface/SimpleTransmission</type>
    <joint name="${ns}_Joint_wrist_3_joint_Safety">
      <hardwareInterface>hardware_interface/PositionJointInterface</hardwareInterface>
    </joint><actuator name="${ns}_Joint_wrist_3_joint_Safety_motor">
      <hardwareInterface>hardware_interface/PositionJointInterface</hardwareInterface>
      <mechanicalReduction>1</mechanicalReduction>
    </actuator>
  </transmission><transmission name="${ns}_Joint_soft_gripper_finger_joint_Safety_trans">
    <type>transmission_interface/SimpleTransmission</type>
    <joint name="${ns}_Joint_soft_gripper_finger_joint_Safety">
      <hardwareInterface>hardware_interface/PositionJointInterface</hardwareInterface>
    </joint><actuator name="${ns}_Joint_soft_gripper_finger_joint_Safety_motor">
      <hardwareInterface>hardware_interface/PositionJointInterface</hardwareInterface>
      <mechanicalReduction>1</mechanicalReduction>
    </actuator>
  </transmission><transmission name="${ns}_Visual_base_link_0_trans">
    <type>transmission_interface/SimpleTransmission</type>
    <joint name="${ns}_Visual_base_link_0">
      <hardwareInterface>hardware_interface/PositionJointInterface</hardwareInterface>
    </joint><actuator name="${ns}_Visual_base_link_0_motor">
      <hardwareInterface>hardware_interface/PositionJointInterface</hardwareInterface>
      <mechanicalReduction>1</mechanicalReduction>
    </actuator>
  </transmission><transmission name="${ns}_Visual_base_link_1_trans">
    <type>transmission_interface/SimpleTransmission</type>
    <joint name="${ns}_Visual_base_link_1">
      <hardwareInterface>hardware_interface/PositionJointInterface</hardwareInterface>
    </joint><actuator name="${ns}_Visual_base_link_1_motor">
      <hardwareInterface>hardware_interface/PositionJointInterface</hardwareInterface>
      <mechanicalReduction>1</mechanicalReduction>
    </actuator>
  </transmission><transmission name="${ns}_Visual_shoulder_link_0_trans">
    <type>transmission_interface/SimpleTransmission</type>
    <joint name="${ns}_Visual_shoulder_link_0">
      <hardwareInterface>hardware_interface/PositionJointInterface</hardwareInterface>
    </joint><actuator name="${ns}_Visual_shoulder_link_0_motor">
      <hardwareInterface>hardware_interface/PositionJointInterface</hardwareInterface>
      <mechanicalReduction>1</mechanicalReduction>
    </actuator>
  </transmission><transmission name="${ns}_Visual_shoulder_link_1_trans">
    <type>transmission_interface/SimpleTransmission</type>
    <joint name="${ns}_Visual_shoulder_link_1">
      <hardwareInterface>hardware_interface/PositionJointInterface</hardwareInterface>
    </joint><actuator name="${ns}_Visual_shoulder_link_1_motor">
      <hardwareInterface>hardware_interface/PositionJointInterface</hardwareInterface>
      <mechanicalReduction>1</mechanicalReduction>
    </actuator>
  </transmission><transmission name="${ns}_Visual_upper_arm_link_0_trans">
    <type>transmission_interface/SimpleTransmission</type>
    <joint name="${ns}_Visual_upper_arm_link_0">
      <hardwareInterface>hardware_interface/PositionJointInterface</hardwareInterface>
    </joint><actuator name="${ns}_Visual_upper_arm_link_0_motor">
      <hardwareInterface>hardware_interface/PositionJointInterface</hardwareInterface>
      <mechanicalReduction>1</mechanicalReduction>
    </actuator>
  </transmission><transmission name="${ns}_Visual_upper_arm_link_1_trans">
    <type>transmission_interface/SimpleTransmission</type>
    <joint name="${ns}_Visual_upper_arm_link_1">
      <hardwareInterface>hardware_interface/PositionJointInterface</hardwareInterface>
    </joint><actuator name="${ns}_Visual_upper_arm_link_1_motor">
      <hardwareInterface>hardware_interface/PositionJointInterface</hardwareInterface>
      <mechanicalReduction>1</mechanicalReduction>
    </actuator>
  </transmission><transmission name="${ns}_Visual_forearm_link_0_trans">
    <type>transmission_interface/SimpleTransmission</type>
    <joint name="${ns}_Visual_forearm_link_0">
      <hardwareInterface>hardware_interface/PositionJointInterface</hardwareInterface>
    </joint><actuator name="${ns}_Visual_forearm_link_0_motor">
      <hardwareInterface>hardware_interface/PositionJointInterface</hardwareInterface>
      <mechanicalReduction>1</mechanicalReduction>
    </actuator>
  </transmission><transmission name="${ns}_Visual_forearm_link_1_trans">
    <type>transmission_interface/SimpleTransmission</type>
    <joint name="${ns}_Visual_forearm_link_1">
      <hardwareInterface>hardware_interface/PositionJointInterface</hardwareInterface>
    </joint><actuator name="${ns}_Visual_forearm_link_1_motor">
      <hardwareInterface>hardware_interface/PositionJointInterface</hardwareInterface>
      <mechanicalReduction>1</mechanicalReduction>
    </actuator>
  </transmission><transmission name="${ns}_Visual_wrist_1_link_0_trans">
    <type>transmission_interface/SimpleTransmission</type>
    <joint name="${ns}_Visual_wrist_1_link_0">
      <hardwareInterface>hardware_interface/PositionJointInterface</hardwareInterface>
    </joint><actuator name="${ns}_Visual_wrist_1_link_0_motor">
      <hardwareInterface>hardware_interface/PositionJointInterface</hardwareInterface>
      <mechanicalReduction>1</mechanicalReduction>
    </actuator>
  </transmission><transmission name="${ns}_Visual_wrist_1_link_1_trans">
    <type>transmission_interface/SimpleTransmission</type>
    <joint name="${ns}_Visual_wrist_1_link_1">
      <hardwareInterface>hardware_interface/PositionJointInterface</hardwareInterface>
    </joint><actuator name="${ns}_Visual_wrist_1_link_1_motor">
      <hardwareInterface>hardware_interface/PositionJointInterface</hardwareInterface>
      <mechanicalReduction>1</mechanicalReduction>
    </actuator>
  </transmission><transmission name="${ns}_Visual_wrist_2_link_0_trans">
    <type>transmission_interface/SimpleTransmission</type>
    <joint name="${ns}_Visual_wrist_2_link_0">
      <hardwareInterface>hardware_interface/PositionJointInterface</hardwareInterface>
    </joint><actuator name="${ns}_Visual_wrist_2_link_0_motor">
      <hardwareInterface>hardware_interface/PositionJointInterface</hardwareInterface>
      <mechanicalReduction>1</mechanicalReduction>
    </actuator>
  </transmission><transmission name="${ns}_Visual_wrist_2_link_1_trans">
    <type>transmission_interface/SimpleTransmission</type>
    <joint name="${ns}_Visual_wrist_2_link_1">
      <hardwareInterface>hardware_interface/PositionJointInterface</hardwareInterface>
    </joint><actuator name="${ns}_Visual_wrist_2_link_1_motor">
      <hardwareInterface>hardware_interface/PositionJointInterface</hardwareInterface>
      <mechanicalReduction>1</mechanicalReduction>
    </actuator>
  </transmission><transmission name="${ns}_Visual_wrist_3_link_0_trans">
    <type>transmission_interface/SimpleTransmission</type>
    <joint name="${ns}_Visual_wrist_3_link_0">
      <hardwareInterface>hardware_interface/PositionJointInterface</hardwareInterface>
    </joint><actuator name="${ns}_Visual_wrist_3_link_0_motor">
      <hardwareInterface>hardware_interface/PositionJointInterface</hardwareInterface>
      <mechanicalReduction>1</mechanicalReduction>
    </actuator>
  </transmission><transmission name="${ns}_Visual_wrist_3_link_1_trans">
    <type>transmission_interface/SimpleTransmission</type>
    <joint name="${ns}_Visual_wrist_3_link_1">
      <hardwareInterface>hardware_interface/PositionJointInterface</hardwareInterface>
    </joint><actuator name="${ns}_Visual_wrist_3_link_1_motor">
      <hardwareInterface>hardware_interface/PositionJointInterface</hardwareInterface>
      <mechanicalReduction>1</mechanicalReduction>
    </actuator>
  </transmission><transmission name="${ns}_Visual_tool0_0_trans">
    <type>transmission_interface/SimpleTransmission</type>
    <joint name="${ns}_Visual_tool0_0">
      <hardwareInterface>hardware_interface/PositionJointInterface</hardwareInterface>
    </joint><actuator name="${ns}_Visual_tool0_0_motor">
      <hardwareInterface>hardware_interface/PositionJointInterface</hardwareInterface>
      <mechanicalReduction>1</mechanicalReduction>
    </actuator>
  </transmission><transmission name="${ns}_Visual_tool0_1_trans">
    <type>transmission_interface/SimpleTransmission</type>
    <joint name="${ns}_Visual_tool0_1">
      <hardwareInterface>hardware_interface/PositionJointInterface</hardwareInterface>
    </joint><actuator name="${ns}_Visual_tool0_1_motor">
      <hardwareInterface>hardware_interface/PositionJointInterface</hardwareInterface>
      <mechanicalReduction>1</mechanicalReduction>
    </actuator>
  </transmission><transmission name="${ns}_Visual_soft_gripper_base_link_0_trans">
    <type>transmission_interface/SimpleTransmission</type>
    <joint name="${ns}_Visual_soft_gripper_base_link_0">
      <hardwareInterface>hardware_interface/PositionJointInterface</hardwareInterface>
    </joint><actuator name="${ns}_Visual_soft_gripper_base_link_0_motor">
      <hardwareInterface>hardware_interface/PositionJointInterface</hardwareInterface>
      <mechanicalReduction>1</mechanicalReduction>
    </actuator>
  </transmission><transmission name="${ns}_Visual_soft_gripper_base_link_1_trans">
    <type>transmission_interface/SimpleTransmission</type>
    <joint name="${ns}_Visual_soft_gripper_base_link_1">
      <hardwareInterface>hardware_interface/PositionJointInterface</hardwareInterface>
    </joint><actuator name="${ns}_Visual_soft_gripper_base_link_1_motor">
      <hardwareInterface>hardware_interface/PositionJointInterface</hardwareInterface>
      <mechanicalReduction>1</mechanicalReduction>
    </actuator>
  </transmission><transmission name="${ns}_Visual_soft_gripper_finger_link_0_trans">
    <type>transmission_interface/SimpleTransmission</type>
    <joint name="${ns}_Visual_soft_gripper_finger_link_0">
      <hardwareInterface>hardware_interface/PositionJointInterface</hardwareInterface>
    </joint><actuator name="${ns}_Visual_soft_gripper_finger_link_0_motor">
      <hardwareInterface>hardware_interface/PositionJointInterface</hardwareInterface>
      <mechanicalReduction>1</mechanicalReduction>
    </actuator>
  </transmission><transmission name="${ns}_Visual_soft_gripper_finger_link_1_trans">
    <type>transmission_interface/SimpleTransmission</type>
    <joint name="${ns}_Visual_soft_gripper_finger_link_1">
      <hardwareInterface>hardware_interface/PositionJointInterface</hardwareInterface>
    </joint><actuator name="${ns}_Visual_soft_gripper_finger_link_1_motor">
      <hardwareInterface>hardware_interface/PositionJointInterface</hardwareInterface>
      <mechanicalReduction>1</mechanicalReduction>
    </actuator>
  </transmission><transmission name="${ns}_Visual_camera_link_0_trans">
    <type>transmission_interface/SimpleTransmission</type>
    <joint name="${ns}_Visual_camera_link_0">
      <hardwareInterface>hardware_interface/PositionJointInterface</hardwareInterface>
    </joint><actuator name="${ns}_Visual_camera_link_0_motor">
      <hardwareInterface>hardware_interface/PositionJointInterface</hardwareInterface>
      <mechanicalReduction>1</mechanicalReduction>
    </actuator>
  </transmission><transmission name="${ns}_Visual_camera_link_1_trans">
    <type>transmission_interface/SimpleTransmission</type>
    <joint name="${ns}_Visual_camera_link_1">
      <hardwareInterface>hardware_interface/PositionJointInterface</hardwareInterface>
    </joint><actuator name="${ns}_Visual_camera_link_1_motor">
      <hardwareInterface>hardware_interface/PositionJointInterface</hardwareInterface>
      <mechanicalReduction>1</mechanicalReduction>
    </actuator>
  </transmission><transmission name="${ns}_Visual_camera_optical_frame_0_trans">
    <type>transmission_interface/SimpleTransmission</type>
    <joint name="${ns}_Visual_camera_optical_frame_0">
      <hardwareInterface>hardware_interface/PositionJointInterface</hardwareInterface>
    </joint><actuator name="${ns}_Visual_camera_optical_frame_0_motor">
      <hardwareInterface>hardware_interface/PositionJointInterface</hardwareInterface>
      <mechanicalReduction>1</mechanicalReduction>
    </actuator>
  </transmission>
</robot>