<?xml version="1.0" ?>
<!-- =================================================================================== -->
<!-- |    This document was autogenerated by xacro from src/iRC_ROS/irc_ros_description/urdf/igus_rebel_6dof.urdf.xacro | -->
<!-- |    EDITING THIS FILE BY HAND IS NOT RECOMMENDED                                 | -->
<!-- =================================================================================== -->
<robot name="igus_rebel_6dof">
  <link name="base_link">
    <visual>
      <geometry>
        <mesh filename="file:///home/unvrx/ros_ws/install/irc_ros_description/share/irc_ros_description/meshes/igus_rebel_6dof_00/Joint0.dae"/>
      </geometry>
    </visual>
    <collision>
      <geometry>
        <mesh filename="file:///home/unvrx/ros_ws/install/irc_ros_description/share/irc_ros_description/meshes/igus_rebel_6dof_00/Joint0Coll.dae"/>
      </geometry>
    </collision>
    <inertial>
      <mass value="1.0"/>
      <inertia ixx="1.0" ixy="0.0" ixz="0.0" iyy="1.0" iyz="0.0" izz="1.0"/>
    </inertial>
  </link>
  <joint name="joint1" type="revolute">
    <parent link="base_link"/>
    <child link="link_1"/>
    <origin rpy="0.0 0.0 0.0" xyz="0.0 0 0.100"/>
    <axis xyz="0 0 -1"/>
    <limit effort="330.0" lower="-3.12413936106985" upper="3.12413936106985" velocity="0.7853981633974483"/>
  </joint>
  <link name="link_1">
    <visual>
      <geometry>
        <mesh filename="file:///home/unvrx/ros_ws/install/irc_ros_description/share/irc_ros_description/meshes/igus_rebel_6dof_00/Joint1.dae"/>
      </geometry>
      <origin rpy="0 0 0" xyz="0 0 0"/>
    </visual>
    <collision>
      <geometry>
        <mesh filename="file:///home/unvrx/ros_ws/install/irc_ros_description/share/irc_ros_description/meshes/igus_rebel_6dof_00/Joint1Coll.dae"/>
      </geometry>
      <origin rpy="0 0 0" xyz="0 0 0"/>
    </collision>
    <inertial>
      <mass value="0.1"/>
      <inertia ixx="0.03" ixy="0.0" ixz="0.0" iyy="0.03" iyz="0.0" izz="0.03"/>
    </inertial>
  </link>
  <joint name="joint2" type="revolute">
    <parent link="link_1"/>
    <child link="link_2"/>
    <origin rpy="0.0 0.5235987755982988 0.0" xyz="0.0 0 0.149"/>
    <axis xyz="0 1 0"/>
    <!-- pi*2/3 are the physical limits, but to avoid any collisions we set the actual limits lower -->
    <limit effort="330.0" lower="-1.9198621771937623" upper="1.9198621771937623" velocity="0.7853981633974483"/>
  </joint>
  <link name="link_2">
    <visual>
      <geometry>
        <mesh filename="file:///home/unvrx/ros_ws/install/irc_ros_description/share/irc_ros_description/meshes/igus_rebel_6dof_00/Joint2.dae"/>
      </geometry>
      <origin rpy="0 0 0" xyz="0 0 0"/>
    </visual>
    <collision>
      <geometry>
        <mesh filename="file:///home/unvrx/ros_ws/install/irc_ros_description/share/irc_ros_description/meshes/igus_rebel_6dof_00/Joint2Coll.dae"/>
      </geometry>
      <origin rpy="0 0 0" xyz="0 0 0"/>
    </collision>
    <inertial>
      <mass value="0.1"/>
      <inertia ixx="0.03" ixy="0.0" ixz="0.0" iyy="0.03" iyz="0.0" izz="0.03"/>
    </inertial>
  </link>
  <joint name="joint3" type="revolute">
    <parent link="link_2"/>
    <child link="link_5"/>
    <origin rpy="0.0 0.5235987755982988 0.0" xyz="0.0 0.0 0.2384"/>
    <axis xyz="0 1 0"/>
    <!-- pi*2/3 are the physical limits, but to avoid any collisions we set the actual limits lower -->
    <limit effort="330.0" lower="-1.9198621771937623" upper="1.9198621771937623" velocity="0.7853981633974483"/>
  </joint>
  <link name="link_5">
    <visual>
      <geometry>
        <mesh filename="file:///home/unvrx/ros_ws/install/irc_ros_description/share/irc_ros_description/meshes/igus_rebel_6dof_00/Joint3.dae"/>
      </geometry>
      <origin rpy="0 0 0" xyz="0 0 0"/>
    </visual>
    <collision>
      <geometry>
        <mesh filename="file:///home/unvrx/ros_ws/install/irc_ros_description/share/irc_ros_description/meshes/igus_rebel_6dof_00/Joint3Coll.dae"/>
      </geometry>
      <origin rpy="0 0 0" xyz="0 0 0"/>
    </collision>
    <inertial>
      <mass value="0.1"/>
      <inertia ixx="0.03" ixy="0.0" ixz="0.0" iyy="0.03" iyz="0.0" izz="0.03"/>
    </inertial>
  </link>
  <joint name="joint4" type="revolute">
    <parent link="link_5"/>
    <child link="link_6"/>
    <!-- TODO The 0.03m offset are most likely caused by the mesh file (Issue 15)-->
    <origin rpy="0.0 0.0 0.0" xyz="0.0 0 0.119"/>
    <axis xyz="0 0 1"/>
    <limit effort="330.0" lower="-3.12413936106985" upper="3.12413936106985" velocity="0.7853981633974483"/>
  </joint>
  <link name="link_6">
    <visual>
      <geometry>
        <mesh filename="file:///home/unvrx/ros_ws/install/irc_ros_description/share/irc_ros_description/meshes/igus_rebel_6dof_00/Joint4.dae"/>
      </geometry>
      <origin rpy="0 0 0" xyz="0 0 0"/>
    </visual>
    <collision>
      <geometry>
        <mesh filename="file:///home/unvrx/ros_ws/install/irc_ros_description/share/irc_ros_description/meshes/igus_rebel_6dof_00/Joint4Coll.dae"/>
      </geometry>
      <origin rpy="0 0 0" xyz="0 0 0"/>
    </collision>
    <inertial>
      <mass value="0.1"/>
      <inertia ixx="0.03" ixy="0.0" ixz="0.0" iyy="0.03" iyz="0.0" izz="0.03"/>
    </inertial>
  </link>
  <joint name="joint5" type="revolute">
    <parent link="link_6"/>
    <child link="link_7"/>
    <!-- TODO The 0.03m offset are most likely caused by the mesh file (Issue 15) -->
    <origin rpy="0.0 -0.1308996938995747 0.0" xyz="0.0 0 0.17"/>
    <axis xyz="0 1 0"/>
    <limit effort="330.0" lower="-1.5271630954950381" upper="1.7889624832941877" velocity="0.7853981633974483"/>
  </joint>
  <link name="link_7">
    <visual>
      <geometry>
        <mesh filename="file:///home/unvrx/ros_ws/install/irc_ros_description/share/irc_ros_description/meshes/igus_rebel_6dof_00/Joint5.dae"/>
      </geometry>
      <origin rpy="0 0 0" xyz="0 0 0"/>
    </visual>
    <collision>
      <geometry>
        <mesh filename="file:///home/unvrx/ros_ws/install/irc_ros_description/share/irc_ros_description/meshes/igus_rebel_6dof_00/Joint5Coll.dae"/>
      </geometry>
      <origin rpy="0 0 0" xyz="0 0 0"/>
    </collision>
    <inertial>
      <mass value="0.1"/>
      <inertia ixx="0.03" ixy="0.0" ixz="0.0" iyy="0.03" iyz="0.0" izz="0.03"/>
    </inertial>
  </link>
  <joint name="joint6" type="revolute">
    <parent link="link_7"/>
    <child link="link_8"/>
    <origin rpy="0.0 0.0 0.0" xyz="0.0 0 0.1208"/>
    <axis xyz="0 0 1"/>
    <limit effort="330.0" lower="-3.12413936106985" upper="3.12413936106985" velocity="0.7853981633974483"/>
  </joint>
  <link name="link_8">
    <visual>
      <geometry>
        <mesh filename="file:///home/unvrx/ros_ws/install/irc_ros_description/share/irc_ros_description/meshes/igus_rebel_6dof_00/Joint6.dae"/>
      </geometry>
      <origin rpy="0 0 0" xyz="0.0 0 0"/>
    </visual>
    <collision>
      <geometry>
        <mesh filename="file:///home/unvrx/ros_ws/install/irc_ros_description/share/irc_ros_description/meshes/igus_rebel_6dof_00/Joint6Coll.dae"/>
      </geometry>
      <origin rpy="0 0 0" xyz="0.0 0 0"/>
    </collision>
    <inertial>
      <mass value="0.1"/>
      <inertia ixx="0.03" ixy="0.0" ixz="0.0" iyy="0.03" iyz="0.0" izz="0.03"/>
    </inertial>
  </link>
  <joint name="joint7" type="fixed">
    <parent link="link_8"/>
    <child link="flange"/>
    <origin rpy="0.0 -1.5707963267948966 0.0" xyz="0.0 0 0.0012"/>
    <axis xyz="0 0 0"/>
  </joint>
  <link name="flange">
    </link>
  <joint name="flange_to_tool0" type="fixed">
    <parent link="flange"/>
    <child link="tool0"/>
    <origin rpy="0.0 0.0 0.0" xyz="0.0 0.0 0.0"/>
    <axis xyz="0 0 0"/>
  </joint>
  <link name="tool0">
    </link>
  <ros2_control name="igus_rebel_6dof" type="system">
    <hardware>
      <plugin>irc_hardware/IrcRosCan</plugin>
      <param name="can_socket">can0</param>
    </hardware>
    <joint name="joint1">
      <command_interface name="position">
        <param name="min">-3.12413936106985</param>
        <param name="max">3.12413936106985</param>
      </command_interface>
      <!-- If you want to increase the velocity and/or speed limit please consult the readme of this package first -->
      <command_interface name="velocity">
        <param name="min">-0.7853981633974483</param>
        <param name="max">0.7853981633974483</param>
      </command_interface>
      <state_interface name="position">
        <param name="initial_value">0.0</param>
      </state_interface>
      <!-- Velocity is required for moveit+mock_components -->
      <state_interface name="velocity">
        <param name="initial_value">0.0</param>
      </state_interface>
      <!-- CPRCAN specific parameters -->
      <param name="can_id">0x10</param>
      <param name="gear_scale">1443.55</param>
      <param name="controller_type">closed_loop</param>
      <!-- CRI specific parameters -->
      <param name="cri_joint_offset">0</param>
    </joint>
    <joint name="joint2">
      <command_interface name="position">
        <param name="min">-2.0943951023931953</param>
        <param name="max">2.0943951023931953</param>
      </command_interface>
      <!-- If you want to increase the velocity and/or speed limit please consult the readme of this package first -->
      <command_interface name="velocity">
        <param name="min">-0.7853981633974483</param>
        <param name="max">0.7853981633974483</param>
      </command_interface>
      <state_interface name="position">
        <param name="initial_value">0.0</param>
      </state_interface>
      <!-- Velocity is required for moveit+mock_components -->
      <state_interface name="velocity">
        <param name="initial_value">0.0</param>
      </state_interface>
      <!-- CPRCAN specific parameters -->
      <param name="can_id">0x20</param>
      <param name="gear_scale">1443.55</param>
      <param name="controller_type">closed_loop</param>
      <!-- CRI specific parameters -->
      <param name="cri_joint_offset">-30</param>
    </joint>
    <joint name="joint3">
      <command_interface name="position">
        <param name="min">-2.0943951023931953</param>
        <param name="max">2.0943951023931953</param>
      </command_interface>
      <!-- If you want to increase the velocity and/or speed limit please consult the readme of this package first -->
      <command_interface name="velocity">
        <param name="min">-0.7853981633974483</param>
        <param name="max">0.7853981633974483</param>
      </command_interface>
      <state_interface name="position">
        <param name="initial_value">0.0</param>
      </state_interface>
      <!-- Velocity is required for moveit+mock_components -->
      <state_interface name="velocity">
        <param name="initial_value">0.0</param>
      </state_interface>
      <!-- CPRCAN specific parameters -->
      <param name="can_id">0x30</param>
      <param name="gear_scale">1443.55</param>
      <param name="controller_type">closed_loop</param>
      <!-- CRI specific parameters -->
      <param name="cri_joint_offset">-30</param>
    </joint>
    <joint name="joint4">
      <command_interface name="position">
        <param name="min">-3.12413936106985</param>
        <param name="max">3.12413936106985</param>
      </command_interface>
      <!-- If you want to increase the velocity and/or speed limit please consult the readme of this package first -->
      <command_interface name="velocity">
        <param name="min">-0.7853981633974483</param>
        <param name="max">0.7853981633974483</param>
      </command_interface>
      <state_interface name="position">
        <param name="initial_value">0.0</param>
      </state_interface>
      <!-- Velocity is required for moveit+mock_components -->
      <state_interface name="velocity">
        <param name="initial_value">0.0</param>
      </state_interface>
      <!-- CPRCAN specific parameters -->
      <param name="can_id">0x40</param>
      <param name="gear_scale">-1443.55</param>
      <param name="controller_type">closed_loop</param>
      <!-- CRI specific parameters -->
      <param name="cri_joint_offset">0</param>
    </joint>
    <joint name="joint5">
      <command_interface name="position">
        <param name="min">-1.658062789394613</param>
        <param name="max">1.658062789394613</param>
      </command_interface>
      <!-- If you want to increase the velocity and/or speed limit please consult the readme of this package first -->
      <command_interface name="velocity">
        <param name="min">-0.7853981633974483</param>
        <param name="max">0.7853981633974483</param>
      </command_interface>
      <state_interface name="position">
        <param name="initial_value">0.0</param>
      </state_interface>
      <!-- Velocity is required for moveit+mock_components -->
      <state_interface name="velocity">
        <param name="initial_value">0.0</param>
      </state_interface>
      <!-- CPRCAN specific parameters -->
      <param name="can_id">0x50</param>
      <param name="gear_scale">1031.11</param>
      <param name="controller_type">closed_loop</param>
      <!-- CRI specific parameters -->
      <param name="cri_joint_offset">7.5</param>
    </joint>
    <joint name="joint6">
      <command_interface name="position">
        <param name="min">-3.12413936106985</param>
        <param name="max">3.12413936106985</param>
      </command_interface>
      <!-- If you want to increase the velocity and/or speed limit please consult the readme of this package first -->
      <command_interface name="velocity">
        <param name="min">-0.7853981633974483</param>
        <param name="max">0.7853981633974483</param>
      </command_interface>
      <state_interface name="position">
        <param name="initial_value">0.0</param>
      </state_interface>
      <!-- Velocity is required for moveit+mock_components -->
      <state_interface name="velocity">
        <param name="initial_value">0.0</param>
      </state_interface>
      <!-- CPRCAN specific parameters -->
      <param name="can_id">0x60</param>
      <param name="gear_scale">-1031.11</param>
      <param name="controller_type">closed_loop</param>
      <!-- CRI specific parameters -->
      <param name="cri_joint_offset">0</param>
    </joint>
    <gpio name="dio_base">
      <param name="can_id">0x70</param>
      <command_interface data_type="bool" name="digital_output_0"/>
      <command_interface data_type="bool" name="digital_output_1"/>
      <command_interface data_type="bool" name="digital_output_2"/>
      <command_interface data_type="bool" name="digital_output_3"/>
      <command_interface data_type="bool" name="digital_output_4"/>
      <command_interface data_type="bool" name="digital_output_5"/>
      <command_interface data_type="bool" name="digital_output_6"/>
      <state_interface data_type="bool" name="digital_input_0"/>
      <state_interface data_type="bool" name="digital_input_1"/>
      <state_interface data_type="bool" name="digital_input_2"/>
      <state_interface data_type="bool" name="digital_input_3"/>
      <state_interface data_type="bool" name="digital_input_4"/>
      <state_interface data_type="bool" name="digital_input_5"/>
      <state_interface data_type="bool" name="digital_input_6"/>
    </gpio>
    <gpio name="dio_arm">
      <param name="can_id">0x80</param>
      <command_interface data_type="bool" name="digital_output_0"/>
      <command_interface data_type="bool" name="digital_output_1"/>
      <state_interface data_type="bool" name="digital_input_0"/>
      <state_interface data_type="bool" name="digital_input_1"/>
    </gpio>
  </ros2_control>
  <!-- Add world link -->
  <link name="world"/>
  <joint name="world_to_base" type="fixed">
    <parent link="world"/>
    <child link="base_link"/>
    <origin rpy="0.0 0.0 0.0" xyz="0.0 0.0 0.0"/>
  </joint>
  <!-- Make sure tcp exists even if no tool is attached -->
  <joint name="flange_to_tcp" type="fixed">
    <parent link="flange"/>
    <child link="tcp"/>
    <origin rpy="0.0 0.0 0.0" xyz="0.0 0.0 0.0"/>
    <axis xyz="0 0 0"/>
  </joint>
  <link name="tcp">
    <inertial>
      <mass value="0.1"/>
      <inertia ixx="0.03" ixy="0.0" ixz="0.0" iyy="0.03" iyz="0.0" izz="0.03"/>
    </inertial>
  </link>
</robot>
