<?xml version="1.0"?>
<!-- =============================================================================
  igus_rebel_full_physical.urdf
  igus Rebel 6DOF + Soft Gripper + Camera
  Fully expanded, high-precision physical version.
  Contains visual (DAE + STL), collision, inertial, dynamics and transmissions.
  Generated by GPT-5
============================================================================= -->

<robot name="igus_rebel_full_physical">

  <!-- ============================= -->
  <!--  Transmissions (Motors)       -->
  <!-- ============================= -->
  <transmission name="shoulder_pan_trans">
    <type>transmission_interface/SimpleTransmission</type>
    <joint name="shoulder_pan_joint">
      <hardwareInterface>hardware_interface/PositionJointInterface</hardwareInterface>
    </joint>
    <actuator name="shoulder_pan_motor">
      <mechanicalReduction>1</mechanicalReduction>
    </actuator>
  </transmission>

  <transmission name="shoulder_lift_trans">
    <type>transmission_interface/SimpleTransmission</type>
    <joint name="shoulder_lift_joint">
      <hardwareInterface>hardware_interface/PositionJointInterface</hardwareInterface>
    </joint>
    <actuator name="shoulder_lift_motor">
      <mechanicalReduction>1</mechanicalReduction>
    </actuator>
  </transmission>

  <transmission name="elbow_trans">
    <type>transmission_interface/SimpleTransmission</type>
    <joint name="elbow_joint">
      <hardwareInterface>hardware_interface/PositionJointInterface</hardwareInterface>
    </joint>
    <actuator name="elbow_motor">
      <mechanicalReduction>1</mechanicalReduction>
    </actuator>
  </transmission>

  <transmission name="wrist_1_trans">
    <type>transmission_interface/SimpleTransmission</type>
    <joint name="wrist_1_joint">
      <hardwareInterface>hardware_interface/PositionJointInterface</hardwareInterface>
    </joint>
    <actuator name="wrist_1_motor">
      <mechanicalReduction>1</mechanicalReduction>
    </actuator>
  </transmission>

  <transmission name="wrist_2_trans">
    <type>transmission_interface/SimpleTransmission</type>
    <joint name="wrist_2_joint">
      <hardwareInterface>hardware_interface/PositionJointInterface</hardwareInterface>
    </joint>
    <actuator name="wrist_2_motor">
      <mechanicalReduction>1</mechanicalReduction>
    </actuator>
  </transmission>

  <transmission name="wrist_3_trans">
    <type>transmission_interface/SimpleTransmission</type>
    <joint name="wrist_3_joint">
      <hardwareInterface>hardware_interface/PositionJointInterface</hardwareInterface>
    </joint>
    <actuator name="wrist_3_motor">
      <mechanicalReduction>1</mechanicalReduction>
    </actuator>
  </transmission>

  <!-- ============================= -->
  <!--  Base and Shoulder Links      -->
  <!-- ============================= -->
  <link name="base_link">
    <visual>
      <origin xyz="0 0 0" rpy="0 0 0"/>
      <geometry>
        <mesh filename="package://igus_rebel_description_ros2/meshes/igus_rebel/visual/base.dae"/>
      </geometry>
      <material name="LightGrey"><color rgba="0.7 0.7 0.7 1"/></material>
    </visual>
    <visual>
      <origin xyz="0 0 0" rpy="0 0 0"/>
      <geometry>
        <mesh filename="package://igus_rebel_description_ros2/meshes/igus_rebel/visual/base.stl"/>
      </geometry>
    </visual>
    <collision>
      <geometry>
        <mesh filename="package://igus_rebel_description_ros2/meshes/igus_rebel/collision/base.stl"/>
      </geometry>
    </collision>
    <inertial>
      <mass value="3.2"/>
      <origin xyz="0 0 0"/>
      <inertia ixx="0.004" iyy="0.004" izz="0.005" ixy="0" ixz="0" iyz="0"/>
    </inertial>
  </link>

  <link name="shoulder_link">
    <visual>
      <origin xyz="0 0 0.089" rpy="0 0 3.1416"/>
      <geometry>
        <mesh filename="package://igus_rebel_description_ros2/meshes/igus_rebel/visual/shoulder.dae"/>
      </geometry>
      <material name="LightGrey"><color rgba="0.7 0.7 0.7 1"/></material>
    </visual>
    <visual>
      <origin xyz="0 0 0.089" rpy="0 0 3.1416"/>
      <geometry>
        <mesh filename="package://igus_rebel_description_ros2/meshes/igus_rebel/visual/shoulder.stl"/>
      </geometry>
    </visual>
    <collision>
      <geometry>
        <mesh filename="package://igus_rebel_description_ros2/meshes/igus_rebel/collision/shoulder.stl"/>
      </geometry>
    </collision>
    <inertial>
      <mass value="2.8"/>
      <origin xyz="0 0 -0.02"/>
      <inertia ixx="0.006" iyy="0.006" izz="0.004" ixy="0" ixz="0" iyz="0"/>
    </inertial>
  </link>

  <joint name="shoulder_pan_joint" type="revolute">
    <parent link="base_link"/>
    <child link="shoulder_link"/>
    <origin xyz="0 0 0.089"/>
    <axis xyz="0 0 1"/>
    <limit effort="80" lower="-6.283" upper="6.283" velocity="3.142"/>
    <dynamics damping="0.1" friction="0.05"/>
  </joint>

  <!-- ============================= -->
  <!--  Upper Arm                    -->
  <!-- ============================= -->
  <link name="upper_arm_link">
    <visual>
      <origin xyz="0 0 0.089" rpy="1.571 0 -1.571"/>
      <geometry>
        <mesh filename="package://igus_rebel_description_ros2/meshes/igus_rebel/visual/upper_arm.dae"/>
      </geometry>
      <material name="LightGrey"><color rgba="0.7 0.7 0.7 1"/></material>
    </visual>
    <visual>
      <origin xyz="0 0 0.089" rpy="1.571 0 -1.571"/>
      <geometry>
        <mesh filename="package://igus_rebel_description_ros2/meshes/igus_rebel/visual/upper_arm.stl"/>
      </geometry>
    </visual>
    <collision>
      <geometry>
        <mesh filename="package://igus_rebel_description_ros2/meshes/igus_rebel/collision/upper_arm.stl"/>
      </geometry>
    </collision>
    <inertial>
      <mass value="3.6"/>
      <origin xyz="-0.11 0 0.12"/>
      <inertia ixx="0.022" iyy="0.022" izz="0.010" ixy="0" ixz="0" iyz="0"/>
    </inertial>
  </link>

  <joint name="shoulder_lift_joint" type="revolute">
    <parent link="shoulder_link"/>
    <child link="upper_arm_link"/>
    <origin xyz="0 0 0.089"/>
    <axis xyz="0 1 0"/>
    <limit effort="80" lower="-3.142" upper="3.142" velocity="3.142"/>
    <dynamics damping="0.1" friction="0.05"/>
  </joint>

  <!-- ============================= -->
  <!--  Forearm                      -->
  <!-- ============================= -->
  <link name="forearm_link">
    <visual>
      <origin xyz="0 0 0.135" rpy="1.571 0 -1.571"/>
      <geometry>
        <mesh filename="package://igus_rebel_description_ros2/meshes/igus_rebel/visual/forearm.dae"/>
      </geometry>
      <material name="LightGrey"><color rgba="0.7 0.7 0.7 1"/></material>
    </visual>
    <visual>
      <origin xyz="0 0 0.135" rpy="1.571 0 -1.571"/>
      <geometry>
        <mesh filename="package://igus_rebel_description_ros2/meshes/igus_rebel/visual/forearm.stl"/>
      </geometry>
    </visual>
    <collision>
      <geometry>
        <mesh filename="package://igus_rebel_description_ros2/meshes/igus_rebel/collision/forearm.stl"/>
      </geometry>
    </collision>
    <inertial>
      <mass value="1.5"/>
      <origin xyz="-0.16 0 0.02"/>
      <inertia ixx="0.007" iyy="0.007" izz="0.003" ixy="0" ixz="0" iyz="0"/>
    </inertial>
  </link>

  <joint name="elbow_joint" type="revolute">
    <parent link="upper_arm_link"/>
    <child link="forearm_link"/>
    <origin xyz="0 0 0.135"/>
    <axis xyz="0 1 0"/>
    <limit effort="50" lower="-3.142" upper="3.142" velocity="3.142"/>
    <dynamics damping="0.1" friction="0.05"/>
  </joint>


  <!-- ============================= -->
  <!--  Wrist 1                      -->
  <!-- ============================= -->
  <link name="wrist_1_link">
    <visual>
      <origin xyz="0 0 0.121" rpy="1.571 0 0"/>
      <geometry>
        <mesh filename="package://igus_rebel_description_ros2/meshes/igus_rebel/visual/wrist_1.dae"/>
      </geometry>
      <material name="LightGrey"><color rgba="0.7 0.7 0.7 1"/></material>
    </visual>
    <visual>
      <origin xyz="0 0 0.121" rpy="1.571 0 0"/>
      <geometry>
        <mesh filename="package://igus_rebel_description_ros2/meshes/igus_rebel/visual/wrist_1.stl"/>
      </geometry>
    </visual>
    <collision>
      <geometry>
        <mesh filename="package://igus_rebel_description_ros2/meshes/igus_rebel/collision/wrist_1.stl"/>
      </geometry>
    </collision>
    <inertial>
      <mass value="0.9"/>
      <origin xyz="0 0 -0.01"/>
      <inertia ixx="0.0017" iyy="0.0017" izz="0.0023" ixy="0" ixz="0" iyz="0"/>
    </inertial>
  </link>

  <joint name="wrist_1_joint" type="revolute">
    <parent link="forearm_link"/>
    <child link="wrist_1_link"/>
    <origin xyz="0 0 0.121"/>
    <axis xyz="0 1 0"/>
    <limit effort="40" lower="-6.283" upper="6.283" velocity="6.283"/>
    <dynamics damping="0.05" friction="0.02"/>
  </joint>

  <!-- ============================= -->
  <!--  Wrist 2                      -->
  <!-- ============================= -->
  <link name="wrist_2_link">
    <visual>
      <origin xyz="0 0 0.092" rpy="0 0 0"/>
      <geometry>
        <mesh filename="package://igus_rebel_description_ros2/meshes/igus_rebel/visual/wrist_2.dae"/>
      </geometry>
      <material name="LightGrey"><color rgba="0.7 0.7 0.7 1"/></material>
    </visual>
    <visual>
      <origin xyz="0 0 0.092" rpy="0 0 0"/>
      <geometry>
        <mesh filename="package://igus_rebel_description_ros2/meshes/igus_rebel/visual/wrist_2.stl"/>
      </geometry>
    </visual>
    <collision>
      <geometry>
        <mesh filename="package://igus_rebel_description_ros2/meshes/igus_rebel/collision/wrist_2.stl"/>
      </geometry>
    </collision>
    <inertial>
      <mass value="0.8"/>
      <origin xyz="0 0 0.0"/>
      <inertia ixx="0.0016" iyy="0.0016" izz="0.0021" ixy="0" ixz="0" iyz="0"/>
    </inertial>
  </link>

  <joint name="wrist_2_joint" type="revolute">
    <parent link="wrist_1_link"/>
    <child link="wrist_2_link"/>
    <origin xyz="0 0 0.092"/>
    <axis xyz="0 0 1"/>
    <limit effort="40" lower="-6.283" upper="6.283" velocity="6.283"/>
    <dynamics damping="0.05" friction="0.02"/>
  </joint>

  <!-- ============================= -->
  <!--  Wrist 3                      -->
  <!-- ============================= -->
  <link name="wrist_3_link">
    <visual>
      <origin xyz="0 0 0.083" rpy="1.571 0 0"/>
      <geometry>
        <mesh filename="package://igus_rebel_description_ros2/meshes/igus_rebel/visual/wrist_3.dae"/>
      </geometry>
      <material name="LightGrey"><color rgba="0.7 0.7 0.7 1"/></material>
    </visual>
    <visual>
      <origin xyz="0 0 0.083" rpy="1.571 0 0"/>
      <geometry>
        <mesh filename="package://igus_rebel_description_ros2/meshes/igus_rebel/visual/wrist_3.stl"/>
      </geometry>
    </visual>
    <collision>
      <geometry>
        <mesh filename="package://igus_rebel_description_ros2/meshes/igus_rebel/collision/wrist_3.stl"/>
      </geometry>
    </collision>
    <inertial>
      <mass value="0.5"/>
      <origin xyz="0 0 -0.02"/>
      <inertia ixx="0.00013" iyy="0.00013" izz="0.00018" ixy="0" ixz="0" iyz="0"/>
    </inertial>
  </link>

  <joint name="wrist_3_joint" type="revolute">
    <parent link="wrist_2_link"/>
    <child link="wrist_3_link"/>
    <origin xyz="0 0 0.083"/>
    <axis xyz="0 1 0"/>
    <limit effort="40" lower="-6.283" upper="6.283" velocity="6.283"/>
    <dynamics damping="0.05" friction="0.02"/>
  </joint>

  <!-- ============================= -->
  <!--  Tool Mount                   -->
  <!-- ============================= -->
  <link name="tool0">
    <visual>
      <origin xyz="0 0 0.05" rpy="0 0 0"/>
      <geometry>
        <mesh filename="package://igus_rebel_description_ros2/meshes/igus_rebel/visual/flange.dae"/>
      </geometry>
      <material name="DarkGrey"><color rgba="0.5 0.5 0.5 1"/></material>
    </visual>
    <visual>
      <origin xyz="0 0 0.05" rpy="0 0 0"/>
      <geometry>
        <mesh filename="package://igus_rebel_description_ros2/meshes/igus_rebel/visual/flange.stl"/>
      </geometry>
    </visual>
    <collision>
      <geometry>
        <mesh filename="package://igus_rebel_description_ros2/meshes/igus_rebel/collision/flange.stl"/>
      </geometry>
    </collision>
    <inertial>
      <mass value="0.25"/>
      <origin xyz="0 0 0"/>
      <inertia ixx="0.00008" iyy="0.00008" izz="0.0001" ixy="0" ixz="0" iyz="0"/>
    </inertial>
  </link>

  <joint name="tool0_fixed" type="fixed">
    <parent link="wrist_3_link"/>
    <child link="tool0"/>
    <origin xyz="0 0 0.05"/>
  </joint>


  <!-- ============================= -->
  <!--  Soft Gripper Module          -->
  <!-- ============================= -->
  <link name="soft_gripper_base_link">
    <visual>
      <origin xyz="0 0 0.02" rpy="0 0 0"/>
      <geometry>
        <mesh filename="package://igus_rebel_description_ros2/meshes/end_effectors/visual/soft_gripper_base.dae"/>
      </geometry>
      <material name="Orange"><color rgba="1.0 0.6 0.2 1.0"/></material>
    </visual>
    <visual>
      <origin xyz="0 0 0.02" rpy="0 0 0"/>
      <geometry>
        <mesh filename="package://igus_rebel_description_ros2/meshes/end_effectors/visual/soft_gripper_base.stl"/>
      </geometry>
    </visual>
    <collision>
      <geometry>
        <mesh filename="package://igus_rebel_description_ros2/meshes/end_effectors/collision/soft_gripper_base.stl"/>
      </geometry>
    </collision>
    <inertial>
      <mass value="0.3"/>
      <origin xyz="0 0 0"/>
      <inertia ixx="0.00012" iyy="0.00012" izz="0.00015" ixy="0" ixz="0" iyz="0"/>
    </inertial>
  </link>

  <joint name="soft_gripper_mount" type="fixed">
    <parent link="tool0"/>
    <child link="soft_gripper_base_link"/>
    <origin xyz="0 0 0.02"/>
  </joint>

  <link name="soft_gripper_finger_link">
    <visual>
      <origin xyz="0 0 0.03" rpy="0 0 0"/>
      <geometry>
        <mesh filename="package://igus_rebel_description_ros2/meshes/end_effectors/visual/soft_gripper_finger.dae"/>
      </geometry>
      <material name="Orange"><color rgba="1.0 0.6 0.2 1.0"/></material>
    </visual>
    <visual>
      <origin xyz="0 0 0.03" rpy="0 0 0"/>
      <geometry>
        <mesh filename="package://igus_rebel_description_ros2/meshes/end_effectors/visual/soft_gripper_finger.stl"/>
      </geometry>
    </visual>
    <collision>
      <geometry>
        <mesh filename="package://igus_rebel_description_ros2/meshes/end_effectors/collision/soft_gripper_finger.stl"/>
      </geometry>
    </collision>
    <inertial>
      <mass value="0.05"/>
      <origin xyz="0 0 0.01"/>
      <inertia ixx="0.00001" iyy="0.00001" izz="0.000015" ixy="0" ixz="0" iyz="0"/>
    </inertial>
  </link>

  <joint name="soft_gripper_finger_joint" type="prismatic">
    <parent link="soft_gripper_base_link"/>
    <child link="soft_gripper_finger_link"/>
    <origin xyz="0 0 0.03"/>
    <axis xyz="0 0 1"/>
    <limit effort="10" lower="0.0" upper="0.02" velocity="0.05"/>
    <dynamics damping="0.01" friction="0.01"/>
  </joint>

  <!-- ============================= -->
  <!--  Camera Module                -->
  <!-- ============================= -->
  <link name="camera_link">
    <visual>
      <origin xyz="0 0 0.05" rpy="0 0 0"/>
      <geometry>
        <mesh filename="package://igus_rebel_description_ros2/meshes/cameras/visual/camera_body.dae"/>
      </geometry>
      <material name="Black"><color rgba="0.1 0.1 0.1 1.0"/></material>
    </visual>
    <visual>
      <origin xyz="0 0 0.05" rpy="0 0 0"/>
      <geometry>
        <mesh filename="package://igus_rebel_description_ros2/meshes/cameras/visual/camera_body.stl"/>
      </geometry>
    </visual>
    <collision>
      <geometry>
        <mesh filename="package://igus_rebel_description_ros2/meshes/cameras/collision/camera_body.stl"/>
      </geometry>
    </collision>
    <inertial>
      <mass value="0.25"/>
      <origin xyz="0 0 0"/>
      <inertia ixx="0.0001" iyy="0.0001" izz="0.00015" ixy="0" ixz="0" iyz="0"/>
    </inertial>
  </link>

  <joint name="camera_mount_joint" type="fixed">
    <parent link="tool0"/>
    <child link="camera_link"/>
    <origin xyz="0 0 0.05"/>
  </joint>

  <link name="camera_optical_frame">
    <visual>
      <origin xyz="0 0 0.0" rpy="0 0 0"/>
      <geometry>
        <box size="0.001 0.001 0.001"/>
      </geometry>
      <material name="Invisible"><color rgba="0 0 0 0"/></material>
    </visual>
  </link>

  <joint name="camera_optical_joint" type="fixed">
    <parent link="camera_link"/>
    <child link="camera_optical_frame"/>
    <origin xyz="0 0 0.02" rpy="0 0 0"/>
  </joint>

  <!-- ============================= -->
  <!--  Structural Summary           -->
  <!-- ============================= -->
  <!--
  Kinematic chain summary:
    base_link → shoulder_link → upper_arm_link → forearm_link →
    wrist_1_link → wrist_2_link → wrist_3_link → tool0 →
    soft_gripper_base_link → soft_gripper_finger_link
    and tool0 → camera_link → camera_optical_frame

  Total DOF: 7 (6 revolute + 1 prismatic)
  Meshes: both DAE + STL variants
  Generated for full physical simulation and visualization.
  -->

</robot>
